[2021-10-26 15:07:34,092] {processor.py:163} INFO - Started process (PID=48) to work on /opt/airflow/dags/first_dag.py
[2021-10-26 15:07:34,096] {processor.py:620} INFO - Processing file /opt/airflow/dags/first_dag.py for tasks to queue
[2021-10-26 15:07:34,098] {logging_mixin.py:109} INFO - [2021-10-26 15:07:34,098] {dagbag.py:500} INFO - Filling up the DagBag from /opt/airflow/dags/first_dag.py
[2021-10-26 15:07:34,201] {logging_mixin.py:109} INFO - All Dag modules are ok
[2021-10-26 15:07:34,228] {logging_mixin.py:109} INFO - [2021-10-26 15:07:34,212] {dagbag.py:334} ERROR - Failed to import: /opt/airflow/dags/first_dag.py
Traceback (most recent call last):
  File "/home/airflow/.local/lib/python3.6/site-packages/airflow/models/dagbag.py", line 331, in _load_modules_from_file
    loader.exec_module(new_module)
  File "<frozen importlib._bootstrap_external>", line 678, in exec_module
  File "<frozen importlib._bootstrap>", line 219, in _call_with_frames_removed
  File "/opt/airflow/dags/first_dag.py", line 43, in <module>
    provide_context=True
  File "/home/airflow/.local/lib/python3.6/site-packages/airflow/models/baseoperator.py", line 188, in apply_defaults
    result = func(self, *args, **kwargs)
  File "/home/airflow/.local/lib/python3.6/site-packages/airflow/operators/python.py", line 135, in __init__
    super().__init__(**kwargs)
  File "/home/airflow/.local/lib/python3.6/site-packages/airflow/models/baseoperator.py", line 188, in apply_defaults
    result = func(self, *args, **kwargs)
  File "/home/airflow/.local/lib/python3.6/site-packages/airflow/models/baseoperator.py", line 553, in __init__
    task_group.add(self)
  File "/home/airflow/.local/lib/python3.6/site-packages/airflow/utils/task_group.py", line 175, in add
    raise DuplicateTaskIdFound(f"Task id '{key}' has already been added to the DAG")
airflow.exceptions.DuplicateTaskIdFound: Task id 'first_function_execute' has already been added to the DAG
[2021-10-26 15:07:34,275] {processor.py:634} WARNING - No viable dags retrieved from /opt/airflow/dags/first_dag.py
[2021-10-26 15:07:34,305] {processor.py:171} INFO - Processing /opt/airflow/dags/first_dag.py took 0.227 seconds
[2021-10-26 15:08:44,868] {processor.py:163} INFO - Started process (PID=384) to work on /opt/airflow/dags/first_dag.py
[2021-10-26 15:08:44,872] {processor.py:620} INFO - Processing file /opt/airflow/dags/first_dag.py for tasks to queue
[2021-10-26 15:08:44,874] {logging_mixin.py:109} INFO - [2021-10-26 15:08:44,874] {dagbag.py:500} INFO - Filling up the DagBag from /opt/airflow/dags/first_dag.py
[2021-10-26 15:08:44,931] {logging_mixin.py:109} INFO - All Dag modules are ok
[2021-10-26 15:08:44,954] {logging_mixin.py:109} INFO - [2021-10-26 15:08:44,936] {dagbag.py:334} ERROR - Failed to import: /opt/airflow/dags/first_dag.py
Traceback (most recent call last):
  File "/home/airflow/.local/lib/python3.6/site-packages/airflow/models/dagbag.py", line 331, in _load_modules_from_file
    loader.exec_module(new_module)
  File "<frozen importlib._bootstrap_external>", line 678, in exec_module
  File "<frozen importlib._bootstrap>", line 219, in _call_with_frames_removed
  File "/opt/airflow/dags/first_dag.py", line 43, in <module>
    provide_context=True
  File "/home/airflow/.local/lib/python3.6/site-packages/airflow/models/baseoperator.py", line 188, in apply_defaults
    result = func(self, *args, **kwargs)
  File "/home/airflow/.local/lib/python3.6/site-packages/airflow/operators/python.py", line 135, in __init__
    super().__init__(**kwargs)
  File "/home/airflow/.local/lib/python3.6/site-packages/airflow/models/baseoperator.py", line 188, in apply_defaults
    result = func(self, *args, **kwargs)
  File "/home/airflow/.local/lib/python3.6/site-packages/airflow/models/baseoperator.py", line 553, in __init__
    task_group.add(self)
  File "/home/airflow/.local/lib/python3.6/site-packages/airflow/utils/task_group.py", line 175, in add
    raise DuplicateTaskIdFound(f"Task id '{key}' has already been added to the DAG")
airflow.exceptions.DuplicateTaskIdFound: Task id 'first_function_execute' has already been added to the DAG
[2021-10-26 15:08:44,990] {processor.py:634} WARNING - No viable dags retrieved from /opt/airflow/dags/first_dag.py
[2021-10-26 15:08:45,005] {processor.py:171} INFO - Processing /opt/airflow/dags/first_dag.py took 0.146 seconds
