[2021-10-27 07:17:40,911] {processor.py:163} INFO - Started process (PID=46) to work on /opt/airflow/dags/first_dag.py
[2021-10-27 07:17:40,915] {processor.py:620} INFO - Processing file /opt/airflow/dags/first_dag.py for tasks to queue
[2021-10-27 07:17:40,919] {logging_mixin.py:109} INFO - [2021-10-27 07:17:40,919] {dagbag.py:500} INFO - Filling up the DagBag from /opt/airflow/dags/first_dag.py
[2021-10-27 07:17:40,988] {logging_mixin.py:109} INFO - All Dag modules are ok
[2021-10-27 07:17:41,001] {logging_mixin.py:109} INFO - [2021-10-27 07:17:40,993] {dagbag.py:334} ERROR - Failed to import: /opt/airflow/dags/first_dag.py
Traceback (most recent call last):
  File "/home/airflow/.local/lib/python3.6/site-packages/airflow/models/dagbag.py", line 331, in _load_modules_from_file
    loader.exec_module(new_module)
  File "<frozen importlib._bootstrap_external>", line 678, in exec_module
  File "<frozen importlib._bootstrap>", line 219, in _call_with_frames_removed
  File "/opt/airflow/dags/first_dag.py", line 43, in <module>
    provide_context=True
  File "/home/airflow/.local/lib/python3.6/site-packages/airflow/models/baseoperator.py", line 188, in apply_defaults
    result = func(self, *args, **kwargs)
  File "/home/airflow/.local/lib/python3.6/site-packages/airflow/operators/python.py", line 135, in __init__
    super().__init__(**kwargs)
  File "/home/airflow/.local/lib/python3.6/site-packages/airflow/models/baseoperator.py", line 188, in apply_defaults
    result = func(self, *args, **kwargs)
  File "/home/airflow/.local/lib/python3.6/site-packages/airflow/models/baseoperator.py", line 553, in __init__
    task_group.add(self)
  File "/home/airflow/.local/lib/python3.6/site-packages/airflow/utils/task_group.py", line 175, in add
    raise DuplicateTaskIdFound(f"Task id '{key}' has already been added to the DAG")
airflow.exceptions.DuplicateTaskIdFound: Task id 'first_function_execute' has already been added to the DAG
[2021-10-27 07:17:41,040] {processor.py:634} WARNING - No viable dags retrieved from /opt/airflow/dags/first_dag.py
[2021-10-27 07:17:41,321] {processor.py:171} INFO - Processing /opt/airflow/dags/first_dag.py took 0.432 seconds
[2021-10-27 07:18:11,455] {processor.py:163} INFO - Started process (PID=102) to work on /opt/airflow/dags/first_dag.py
[2021-10-27 07:18:11,456] {processor.py:620} INFO - Processing file /opt/airflow/dags/first_dag.py for tasks to queue
[2021-10-27 07:18:11,457] {logging_mixin.py:109} INFO - [2021-10-27 07:18:11,457] {dagbag.py:500} INFO - Filling up the DagBag from /opt/airflow/dags/first_dag.py
[2021-10-27 07:18:11,479] {logging_mixin.py:109} INFO - All Dag modules are ok
[2021-10-27 07:18:11,488] {logging_mixin.py:109} INFO - [2021-10-27 07:18:11,481] {dagbag.py:334} ERROR - Failed to import: /opt/airflow/dags/first_dag.py
Traceback (most recent call last):
  File "/home/airflow/.local/lib/python3.6/site-packages/airflow/models/dagbag.py", line 331, in _load_modules_from_file
    loader.exec_module(new_module)
  File "<frozen importlib._bootstrap_external>", line 678, in exec_module
  File "<frozen importlib._bootstrap>", line 219, in _call_with_frames_removed
  File "/opt/airflow/dags/first_dag.py", line 43, in <module>
    provide_context=True
  File "/home/airflow/.local/lib/python3.6/site-packages/airflow/models/baseoperator.py", line 188, in apply_defaults
    result = func(self, *args, **kwargs)
  File "/home/airflow/.local/lib/python3.6/site-packages/airflow/operators/python.py", line 135, in __init__
    super().__init__(**kwargs)
  File "/home/airflow/.local/lib/python3.6/site-packages/airflow/models/baseoperator.py", line 188, in apply_defaults
    result = func(self, *args, **kwargs)
  File "/home/airflow/.local/lib/python3.6/site-packages/airflow/models/baseoperator.py", line 553, in __init__
    task_group.add(self)
  File "/home/airflow/.local/lib/python3.6/site-packages/airflow/utils/task_group.py", line 175, in add
    raise DuplicateTaskIdFound(f"Task id '{key}' has already been added to the DAG")
airflow.exceptions.DuplicateTaskIdFound: Task id 'first_function_execute' has already been added to the DAG
[2021-10-27 07:18:11,506] {processor.py:634} WARNING - No viable dags retrieved from /opt/airflow/dags/first_dag.py
[2021-10-27 07:18:11,515] {processor.py:171} INFO - Processing /opt/airflow/dags/first_dag.py took 0.064 seconds
[2021-10-27 07:18:41,790] {processor.py:163} INFO - Started process (PID=157) to work on /opt/airflow/dags/first_dag.py
[2021-10-27 07:18:41,794] {processor.py:620} INFO - Processing file /opt/airflow/dags/first_dag.py for tasks to queue
[2021-10-27 07:18:41,795] {logging_mixin.py:109} INFO - [2021-10-27 07:18:41,794] {dagbag.py:500} INFO - Filling up the DagBag from /opt/airflow/dags/first_dag.py
[2021-10-27 07:18:41,820] {logging_mixin.py:109} INFO - All Dag modules are ok
[2021-10-27 07:18:41,830] {logging_mixin.py:109} INFO - [2021-10-27 07:18:41,822] {dagbag.py:334} ERROR - Failed to import: /opt/airflow/dags/first_dag.py
Traceback (most recent call last):
  File "/home/airflow/.local/lib/python3.6/site-packages/airflow/models/dagbag.py", line 331, in _load_modules_from_file
    loader.exec_module(new_module)
  File "<frozen importlib._bootstrap_external>", line 678, in exec_module
  File "<frozen importlib._bootstrap>", line 219, in _call_with_frames_removed
  File "/opt/airflow/dags/first_dag.py", line 43, in <module>
    provide_context=True
  File "/home/airflow/.local/lib/python3.6/site-packages/airflow/models/baseoperator.py", line 188, in apply_defaults
    result = func(self, *args, **kwargs)
  File "/home/airflow/.local/lib/python3.6/site-packages/airflow/operators/python.py", line 135, in __init__
    super().__init__(**kwargs)
  File "/home/airflow/.local/lib/python3.6/site-packages/airflow/models/baseoperator.py", line 188, in apply_defaults
    result = func(self, *args, **kwargs)
  File "/home/airflow/.local/lib/python3.6/site-packages/airflow/models/baseoperator.py", line 553, in __init__
    task_group.add(self)
  File "/home/airflow/.local/lib/python3.6/site-packages/airflow/utils/task_group.py", line 175, in add
    raise DuplicateTaskIdFound(f"Task id '{key}' has already been added to the DAG")
airflow.exceptions.DuplicateTaskIdFound: Task id 'first_function_execute' has already been added to the DAG
[2021-10-27 07:18:41,864] {processor.py:634} WARNING - No viable dags retrieved from /opt/airflow/dags/first_dag.py
[2021-10-27 07:18:41,871] {processor.py:171} INFO - Processing /opt/airflow/dags/first_dag.py took 0.084 seconds
[2021-10-27 07:19:11,949] {processor.py:163} INFO - Started process (PID=213) to work on /opt/airflow/dags/first_dag.py
[2021-10-27 07:19:11,951] {processor.py:620} INFO - Processing file /opt/airflow/dags/first_dag.py for tasks to queue
[2021-10-27 07:19:11,952] {logging_mixin.py:109} INFO - [2021-10-27 07:19:11,952] {dagbag.py:500} INFO - Filling up the DagBag from /opt/airflow/dags/first_dag.py
[2021-10-27 07:19:11,995] {logging_mixin.py:109} INFO - All Dag modules are ok
[2021-10-27 07:19:12,005] {logging_mixin.py:109} INFO - [2021-10-27 07:19:11,998] {dagbag.py:334} ERROR - Failed to import: /opt/airflow/dags/first_dag.py
Traceback (most recent call last):
  File "/home/airflow/.local/lib/python3.6/site-packages/airflow/models/dagbag.py", line 331, in _load_modules_from_file
    loader.exec_module(new_module)
  File "<frozen importlib._bootstrap_external>", line 678, in exec_module
  File "<frozen importlib._bootstrap>", line 219, in _call_with_frames_removed
  File "/opt/airflow/dags/first_dag.py", line 43, in <module>
    provide_context=True
  File "/home/airflow/.local/lib/python3.6/site-packages/airflow/models/baseoperator.py", line 188, in apply_defaults
    result = func(self, *args, **kwargs)
  File "/home/airflow/.local/lib/python3.6/site-packages/airflow/operators/python.py", line 135, in __init__
    super().__init__(**kwargs)
  File "/home/airflow/.local/lib/python3.6/site-packages/airflow/models/baseoperator.py", line 188, in apply_defaults
    result = func(self, *args, **kwargs)
  File "/home/airflow/.local/lib/python3.6/site-packages/airflow/models/baseoperator.py", line 553, in __init__
    task_group.add(self)
  File "/home/airflow/.local/lib/python3.6/site-packages/airflow/utils/task_group.py", line 175, in add
    raise DuplicateTaskIdFound(f"Task id '{key}' has already been added to the DAG")
airflow.exceptions.DuplicateTaskIdFound: Task id 'first_function_execute' has already been added to the DAG
[2021-10-27 07:19:12,026] {processor.py:634} WARNING - No viable dags retrieved from /opt/airflow/dags/first_dag.py
[2021-10-27 07:19:12,038] {processor.py:171} INFO - Processing /opt/airflow/dags/first_dag.py took 0.093 seconds
[2021-10-27 07:19:42,793] {processor.py:163} INFO - Started process (PID=277) to work on /opt/airflow/dags/first_dag.py
[2021-10-27 07:19:42,794] {processor.py:620} INFO - Processing file /opt/airflow/dags/first_dag.py for tasks to queue
[2021-10-27 07:19:42,795] {logging_mixin.py:109} INFO - [2021-10-27 07:19:42,795] {dagbag.py:500} INFO - Filling up the DagBag from /opt/airflow/dags/first_dag.py
[2021-10-27 07:19:42,822] {logging_mixin.py:109} INFO - All Dag modules are ok
[2021-10-27 07:19:42,831] {logging_mixin.py:109} INFO - [2021-10-27 07:19:42,824] {dagbag.py:334} ERROR - Failed to import: /opt/airflow/dags/first_dag.py
Traceback (most recent call last):
  File "/home/airflow/.local/lib/python3.6/site-packages/airflow/models/dagbag.py", line 331, in _load_modules_from_file
    loader.exec_module(new_module)
  File "<frozen importlib._bootstrap_external>", line 678, in exec_module
  File "<frozen importlib._bootstrap>", line 219, in _call_with_frames_removed
  File "/opt/airflow/dags/first_dag.py", line 43, in <module>
    provide_context=True
  File "/home/airflow/.local/lib/python3.6/site-packages/airflow/models/baseoperator.py", line 188, in apply_defaults
    result = func(self, *args, **kwargs)
  File "/home/airflow/.local/lib/python3.6/site-packages/airflow/operators/python.py", line 135, in __init__
    super().__init__(**kwargs)
  File "/home/airflow/.local/lib/python3.6/site-packages/airflow/models/baseoperator.py", line 188, in apply_defaults
    result = func(self, *args, **kwargs)
  File "/home/airflow/.local/lib/python3.6/site-packages/airflow/models/baseoperator.py", line 553, in __init__
    task_group.add(self)
  File "/home/airflow/.local/lib/python3.6/site-packages/airflow/utils/task_group.py", line 175, in add
    raise DuplicateTaskIdFound(f"Task id '{key}' has already been added to the DAG")
airflow.exceptions.DuplicateTaskIdFound: Task id 'first_function_execute' has already been added to the DAG
[2021-10-27 07:19:42,847] {processor.py:634} WARNING - No viable dags retrieved from /opt/airflow/dags/first_dag.py
[2021-10-27 07:19:42,858] {processor.py:171} INFO - Processing /opt/airflow/dags/first_dag.py took 0.068 seconds
[2021-10-27 07:20:13,700] {processor.py:163} INFO - Started process (PID=333) to work on /opt/airflow/dags/first_dag.py
[2021-10-27 07:20:13,701] {processor.py:620} INFO - Processing file /opt/airflow/dags/first_dag.py for tasks to queue
[2021-10-27 07:20:13,702] {logging_mixin.py:109} INFO - [2021-10-27 07:20:13,702] {dagbag.py:500} INFO - Filling up the DagBag from /opt/airflow/dags/first_dag.py
[2021-10-27 07:20:13,724] {logging_mixin.py:109} INFO - All Dag modules are ok
[2021-10-27 07:20:13,733] {logging_mixin.py:109} INFO - [2021-10-27 07:20:13,726] {dagbag.py:334} ERROR - Failed to import: /opt/airflow/dags/first_dag.py
Traceback (most recent call last):
  File "/home/airflow/.local/lib/python3.6/site-packages/airflow/models/dagbag.py", line 331, in _load_modules_from_file
    loader.exec_module(new_module)
  File "<frozen importlib._bootstrap_external>", line 678, in exec_module
  File "<frozen importlib._bootstrap>", line 219, in _call_with_frames_removed
  File "/opt/airflow/dags/first_dag.py", line 43, in <module>
    provide_context=True
  File "/home/airflow/.local/lib/python3.6/site-packages/airflow/models/baseoperator.py", line 188, in apply_defaults
    result = func(self, *args, **kwargs)
  File "/home/airflow/.local/lib/python3.6/site-packages/airflow/operators/python.py", line 135, in __init__
    super().__init__(**kwargs)
  File "/home/airflow/.local/lib/python3.6/site-packages/airflow/models/baseoperator.py", line 188, in apply_defaults
    result = func(self, *args, **kwargs)
  File "/home/airflow/.local/lib/python3.6/site-packages/airflow/models/baseoperator.py", line 553, in __init__
    task_group.add(self)
  File "/home/airflow/.local/lib/python3.6/site-packages/airflow/utils/task_group.py", line 175, in add
    raise DuplicateTaskIdFound(f"Task id '{key}' has already been added to the DAG")
airflow.exceptions.DuplicateTaskIdFound: Task id 'first_function_execute' has already been added to the DAG
[2021-10-27 07:20:13,748] {processor.py:634} WARNING - No viable dags retrieved from /opt/airflow/dags/first_dag.py
[2021-10-27 07:20:13,756] {processor.py:171} INFO - Processing /opt/airflow/dags/first_dag.py took 0.060 seconds
[2021-10-27 07:20:44,006] {processor.py:163} INFO - Started process (PID=399) to work on /opt/airflow/dags/first_dag.py
[2021-10-27 07:20:44,008] {processor.py:620} INFO - Processing file /opt/airflow/dags/first_dag.py for tasks to queue
[2021-10-27 07:20:44,009] {logging_mixin.py:109} INFO - [2021-10-27 07:20:44,009] {dagbag.py:500} INFO - Filling up the DagBag from /opt/airflow/dags/first_dag.py
[2021-10-27 07:20:44,038] {logging_mixin.py:109} INFO - All Dag modules are ok
[2021-10-27 07:20:44,047] {logging_mixin.py:109} INFO - [2021-10-27 07:20:44,041] {dagbag.py:334} ERROR - Failed to import: /opt/airflow/dags/first_dag.py
Traceback (most recent call last):
  File "/home/airflow/.local/lib/python3.6/site-packages/airflow/models/dagbag.py", line 331, in _load_modules_from_file
    loader.exec_module(new_module)
  File "<frozen importlib._bootstrap_external>", line 678, in exec_module
  File "<frozen importlib._bootstrap>", line 219, in _call_with_frames_removed
  File "/opt/airflow/dags/first_dag.py", line 43, in <module>
    provide_context=True
  File "/home/airflow/.local/lib/python3.6/site-packages/airflow/models/baseoperator.py", line 188, in apply_defaults
    result = func(self, *args, **kwargs)
  File "/home/airflow/.local/lib/python3.6/site-packages/airflow/operators/python.py", line 135, in __init__
    super().__init__(**kwargs)
  File "/home/airflow/.local/lib/python3.6/site-packages/airflow/models/baseoperator.py", line 188, in apply_defaults
    result = func(self, *args, **kwargs)
  File "/home/airflow/.local/lib/python3.6/site-packages/airflow/models/baseoperator.py", line 553, in __init__
    task_group.add(self)
  File "/home/airflow/.local/lib/python3.6/site-packages/airflow/utils/task_group.py", line 175, in add
    raise DuplicateTaskIdFound(f"Task id '{key}' has already been added to the DAG")
airflow.exceptions.DuplicateTaskIdFound: Task id 'first_function_execute' has already been added to the DAG
[2021-10-27 07:20:44,064] {processor.py:634} WARNING - No viable dags retrieved from /opt/airflow/dags/first_dag.py
[2021-10-27 07:20:44,075] {processor.py:171} INFO - Processing /opt/airflow/dags/first_dag.py took 0.072 seconds
[2021-10-27 07:21:14,236] {processor.py:163} INFO - Started process (PID=454) to work on /opt/airflow/dags/first_dag.py
[2021-10-27 07:21:14,237] {processor.py:620} INFO - Processing file /opt/airflow/dags/first_dag.py for tasks to queue
[2021-10-27 07:21:14,238] {logging_mixin.py:109} INFO - [2021-10-27 07:21:14,238] {dagbag.py:500} INFO - Filling up the DagBag from /opt/airflow/dags/first_dag.py
[2021-10-27 07:21:14,259] {logging_mixin.py:109} INFO - All Dag modules are ok
[2021-10-27 07:21:14,267] {logging_mixin.py:109} INFO - [2021-10-27 07:21:14,261] {dagbag.py:334} ERROR - Failed to import: /opt/airflow/dags/first_dag.py
Traceback (most recent call last):
  File "/home/airflow/.local/lib/python3.6/site-packages/airflow/models/dagbag.py", line 331, in _load_modules_from_file
    loader.exec_module(new_module)
  File "<frozen importlib._bootstrap_external>", line 678, in exec_module
  File "<frozen importlib._bootstrap>", line 219, in _call_with_frames_removed
  File "/opt/airflow/dags/first_dag.py", line 43, in <module>
    provide_context=True
  File "/home/airflow/.local/lib/python3.6/site-packages/airflow/models/baseoperator.py", line 188, in apply_defaults
    result = func(self, *args, **kwargs)
  File "/home/airflow/.local/lib/python3.6/site-packages/airflow/operators/python.py", line 135, in __init__
    super().__init__(**kwargs)
  File "/home/airflow/.local/lib/python3.6/site-packages/airflow/models/baseoperator.py", line 188, in apply_defaults
    result = func(self, *args, **kwargs)
  File "/home/airflow/.local/lib/python3.6/site-packages/airflow/models/baseoperator.py", line 553, in __init__
    task_group.add(self)
  File "/home/airflow/.local/lib/python3.6/site-packages/airflow/utils/task_group.py", line 175, in add
    raise DuplicateTaskIdFound(f"Task id '{key}' has already been added to the DAG")
airflow.exceptions.DuplicateTaskIdFound: Task id 'first_function_execute' has already been added to the DAG
[2021-10-27 07:21:14,282] {processor.py:634} WARNING - No viable dags retrieved from /opt/airflow/dags/first_dag.py
[2021-10-27 07:21:14,290] {processor.py:171} INFO - Processing /opt/airflow/dags/first_dag.py took 0.057 seconds
[2021-10-27 07:21:44,842] {processor.py:163} INFO - Started process (PID=519) to work on /opt/airflow/dags/first_dag.py
[2021-10-27 07:21:44,843] {processor.py:620} INFO - Processing file /opt/airflow/dags/first_dag.py for tasks to queue
[2021-10-27 07:21:44,844] {logging_mixin.py:109} INFO - [2021-10-27 07:21:44,844] {dagbag.py:500} INFO - Filling up the DagBag from /opt/airflow/dags/first_dag.py
[2021-10-27 07:21:44,870] {logging_mixin.py:109} INFO - All Dag modules are ok
[2021-10-27 07:21:44,878] {logging_mixin.py:109} INFO - [2021-10-27 07:21:44,873] {dagbag.py:334} ERROR - Failed to import: /opt/airflow/dags/first_dag.py
Traceback (most recent call last):
  File "/home/airflow/.local/lib/python3.6/site-packages/airflow/models/dagbag.py", line 331, in _load_modules_from_file
    loader.exec_module(new_module)
  File "<frozen importlib._bootstrap_external>", line 678, in exec_module
  File "<frozen importlib._bootstrap>", line 219, in _call_with_frames_removed
  File "/opt/airflow/dags/first_dag.py", line 43, in <module>
    provide_context=True
  File "/home/airflow/.local/lib/python3.6/site-packages/airflow/models/baseoperator.py", line 188, in apply_defaults
    result = func(self, *args, **kwargs)
  File "/home/airflow/.local/lib/python3.6/site-packages/airflow/operators/python.py", line 135, in __init__
    super().__init__(**kwargs)
  File "/home/airflow/.local/lib/python3.6/site-packages/airflow/models/baseoperator.py", line 188, in apply_defaults
    result = func(self, *args, **kwargs)
  File "/home/airflow/.local/lib/python3.6/site-packages/airflow/models/baseoperator.py", line 553, in __init__
    task_group.add(self)
  File "/home/airflow/.local/lib/python3.6/site-packages/airflow/utils/task_group.py", line 175, in add
    raise DuplicateTaskIdFound(f"Task id '{key}' has already been added to the DAG")
airflow.exceptions.DuplicateTaskIdFound: Task id 'first_function_execute' has already been added to the DAG
[2021-10-27 07:21:44,893] {processor.py:634} WARNING - No viable dags retrieved from /opt/airflow/dags/first_dag.py
[2021-10-27 07:21:44,902] {processor.py:171} INFO - Processing /opt/airflow/dags/first_dag.py took 0.063 seconds
[2021-10-27 07:22:15,317] {processor.py:163} INFO - Started process (PID=574) to work on /opt/airflow/dags/first_dag.py
[2021-10-27 07:22:15,319] {processor.py:620} INFO - Processing file /opt/airflow/dags/first_dag.py for tasks to queue
[2021-10-27 07:22:15,320] {logging_mixin.py:109} INFO - [2021-10-27 07:22:15,320] {dagbag.py:500} INFO - Filling up the DagBag from /opt/airflow/dags/first_dag.py
[2021-10-27 07:22:15,345] {logging_mixin.py:109} INFO - All Dag modules are ok
[2021-10-27 07:22:15,354] {logging_mixin.py:109} INFO - [2021-10-27 07:22:15,348] {dagbag.py:334} ERROR - Failed to import: /opt/airflow/dags/first_dag.py
Traceback (most recent call last):
  File "/home/airflow/.local/lib/python3.6/site-packages/airflow/models/dagbag.py", line 331, in _load_modules_from_file
    loader.exec_module(new_module)
  File "<frozen importlib._bootstrap_external>", line 678, in exec_module
  File "<frozen importlib._bootstrap>", line 219, in _call_with_frames_removed
  File "/opt/airflow/dags/first_dag.py", line 43, in <module>
    provide_context=True
  File "/home/airflow/.local/lib/python3.6/site-packages/airflow/models/baseoperator.py", line 188, in apply_defaults
    result = func(self, *args, **kwargs)
  File "/home/airflow/.local/lib/python3.6/site-packages/airflow/operators/python.py", line 135, in __init__
    super().__init__(**kwargs)
  File "/home/airflow/.local/lib/python3.6/site-packages/airflow/models/baseoperator.py", line 188, in apply_defaults
    result = func(self, *args, **kwargs)
  File "/home/airflow/.local/lib/python3.6/site-packages/airflow/models/baseoperator.py", line 553, in __init__
    task_group.add(self)
  File "/home/airflow/.local/lib/python3.6/site-packages/airflow/utils/task_group.py", line 175, in add
    raise DuplicateTaskIdFound(f"Task id '{key}' has already been added to the DAG")
airflow.exceptions.DuplicateTaskIdFound: Task id 'first_function_execute' has already been added to the DAG
[2021-10-27 07:22:15,371] {processor.py:634} WARNING - No viable dags retrieved from /opt/airflow/dags/first_dag.py
[2021-10-27 07:22:15,380] {processor.py:171} INFO - Processing /opt/airflow/dags/first_dag.py took 0.066 seconds
[2021-10-27 07:22:45,510] {processor.py:163} INFO - Started process (PID=639) to work on /opt/airflow/dags/first_dag.py
[2021-10-27 07:22:45,512] {processor.py:620} INFO - Processing file /opt/airflow/dags/first_dag.py for tasks to queue
[2021-10-27 07:22:45,513] {logging_mixin.py:109} INFO - [2021-10-27 07:22:45,513] {dagbag.py:500} INFO - Filling up the DagBag from /opt/airflow/dags/first_dag.py
[2021-10-27 07:22:45,543] {logging_mixin.py:109} INFO - All Dag modules are ok
[2021-10-27 07:22:45,552] {logging_mixin.py:109} INFO - [2021-10-27 07:22:45,545] {dagbag.py:334} ERROR - Failed to import: /opt/airflow/dags/first_dag.py
Traceback (most recent call last):
  File "/home/airflow/.local/lib/python3.6/site-packages/airflow/models/dagbag.py", line 331, in _load_modules_from_file
    loader.exec_module(new_module)
  File "<frozen importlib._bootstrap_external>", line 678, in exec_module
  File "<frozen importlib._bootstrap>", line 219, in _call_with_frames_removed
  File "/opt/airflow/dags/first_dag.py", line 43, in <module>
    provide_context=True
  File "/home/airflow/.local/lib/python3.6/site-packages/airflow/models/baseoperator.py", line 188, in apply_defaults
    result = func(self, *args, **kwargs)
  File "/home/airflow/.local/lib/python3.6/site-packages/airflow/operators/python.py", line 135, in __init__
    super().__init__(**kwargs)
  File "/home/airflow/.local/lib/python3.6/site-packages/airflow/models/baseoperator.py", line 188, in apply_defaults
    result = func(self, *args, **kwargs)
  File "/home/airflow/.local/lib/python3.6/site-packages/airflow/models/baseoperator.py", line 553, in __init__
    task_group.add(self)
  File "/home/airflow/.local/lib/python3.6/site-packages/airflow/utils/task_group.py", line 175, in add
    raise DuplicateTaskIdFound(f"Task id '{key}' has already been added to the DAG")
airflow.exceptions.DuplicateTaskIdFound: Task id 'first_function_execute' has already been added to the DAG
[2021-10-27 07:22:45,568] {processor.py:634} WARNING - No viable dags retrieved from /opt/airflow/dags/first_dag.py
[2021-10-27 07:22:45,576] {processor.py:171} INFO - Processing /opt/airflow/dags/first_dag.py took 0.071 seconds
[2021-10-27 07:23:15,923] {processor.py:163} INFO - Started process (PID=695) to work on /opt/airflow/dags/first_dag.py
[2021-10-27 07:23:15,924] {processor.py:620} INFO - Processing file /opt/airflow/dags/first_dag.py for tasks to queue
[2021-10-27 07:23:15,925] {logging_mixin.py:109} INFO - [2021-10-27 07:23:15,925] {dagbag.py:500} INFO - Filling up the DagBag from /opt/airflow/dags/first_dag.py
[2021-10-27 07:23:15,954] {logging_mixin.py:109} INFO - All Dag modules are ok
[2021-10-27 07:23:15,964] {logging_mixin.py:109} INFO - [2021-10-27 07:23:15,957] {dagbag.py:334} ERROR - Failed to import: /opt/airflow/dags/first_dag.py
Traceback (most recent call last):
  File "/home/airflow/.local/lib/python3.6/site-packages/airflow/models/dagbag.py", line 331, in _load_modules_from_file
    loader.exec_module(new_module)
  File "<frozen importlib._bootstrap_external>", line 678, in exec_module
  File "<frozen importlib._bootstrap>", line 219, in _call_with_frames_removed
  File "/opt/airflow/dags/first_dag.py", line 43, in <module>
    provide_context=True
  File "/home/airflow/.local/lib/python3.6/site-packages/airflow/models/baseoperator.py", line 188, in apply_defaults
    result = func(self, *args, **kwargs)
  File "/home/airflow/.local/lib/python3.6/site-packages/airflow/operators/python.py", line 135, in __init__
    super().__init__(**kwargs)
  File "/home/airflow/.local/lib/python3.6/site-packages/airflow/models/baseoperator.py", line 188, in apply_defaults
    result = func(self, *args, **kwargs)
  File "/home/airflow/.local/lib/python3.6/site-packages/airflow/models/baseoperator.py", line 553, in __init__
    task_group.add(self)
  File "/home/airflow/.local/lib/python3.6/site-packages/airflow/utils/task_group.py", line 175, in add
    raise DuplicateTaskIdFound(f"Task id '{key}' has already been added to the DAG")
airflow.exceptions.DuplicateTaskIdFound: Task id 'first_function_execute' has already been added to the DAG
[2021-10-27 07:23:15,981] {processor.py:634} WARNING - No viable dags retrieved from /opt/airflow/dags/first_dag.py
[2021-10-27 07:23:15,988] {processor.py:171} INFO - Processing /opt/airflow/dags/first_dag.py took 0.069 seconds
[2021-10-27 07:23:46,599] {processor.py:163} INFO - Started process (PID=750) to work on /opt/airflow/dags/first_dag.py
[2021-10-27 07:23:46,601] {processor.py:620} INFO - Processing file /opt/airflow/dags/first_dag.py for tasks to queue
[2021-10-27 07:23:46,601] {logging_mixin.py:109} INFO - [2021-10-27 07:23:46,601] {dagbag.py:500} INFO - Filling up the DagBag from /opt/airflow/dags/first_dag.py
[2021-10-27 07:23:46,633] {logging_mixin.py:109} INFO - All Dag modules are ok
[2021-10-27 07:23:46,643] {logging_mixin.py:109} INFO - [2021-10-27 07:23:46,636] {dagbag.py:334} ERROR - Failed to import: /opt/airflow/dags/first_dag.py
Traceback (most recent call last):
  File "/home/airflow/.local/lib/python3.6/site-packages/airflow/models/dagbag.py", line 331, in _load_modules_from_file
    loader.exec_module(new_module)
  File "<frozen importlib._bootstrap_external>", line 678, in exec_module
  File "<frozen importlib._bootstrap>", line 219, in _call_with_frames_removed
  File "/opt/airflow/dags/first_dag.py", line 43, in <module>
    provide_context=True
  File "/home/airflow/.local/lib/python3.6/site-packages/airflow/models/baseoperator.py", line 188, in apply_defaults
    result = func(self, *args, **kwargs)
  File "/home/airflow/.local/lib/python3.6/site-packages/airflow/operators/python.py", line 135, in __init__
    super().__init__(**kwargs)
  File "/home/airflow/.local/lib/python3.6/site-packages/airflow/models/baseoperator.py", line 188, in apply_defaults
    result = func(self, *args, **kwargs)
  File "/home/airflow/.local/lib/python3.6/site-packages/airflow/models/baseoperator.py", line 553, in __init__
    task_group.add(self)
  File "/home/airflow/.local/lib/python3.6/site-packages/airflow/utils/task_group.py", line 175, in add
    raise DuplicateTaskIdFound(f"Task id '{key}' has already been added to the DAG")
airflow.exceptions.DuplicateTaskIdFound: Task id 'first_function_execute' has already been added to the DAG
[2021-10-27 07:23:46,664] {processor.py:634} WARNING - No viable dags retrieved from /opt/airflow/dags/first_dag.py
[2021-10-27 07:23:46,673] {processor.py:171} INFO - Processing /opt/airflow/dags/first_dag.py took 0.077 seconds
[2021-10-27 07:24:17,385] {processor.py:163} INFO - Started process (PID=815) to work on /opt/airflow/dags/first_dag.py
[2021-10-27 07:24:17,386] {processor.py:620} INFO - Processing file /opt/airflow/dags/first_dag.py for tasks to queue
[2021-10-27 07:24:17,387] {logging_mixin.py:109} INFO - [2021-10-27 07:24:17,387] {dagbag.py:500} INFO - Filling up the DagBag from /opt/airflow/dags/first_dag.py
[2021-10-27 07:24:17,412] {logging_mixin.py:109} INFO - All Dag modules are ok
[2021-10-27 07:24:17,420] {logging_mixin.py:109} INFO - [2021-10-27 07:24:17,414] {dagbag.py:334} ERROR - Failed to import: /opt/airflow/dags/first_dag.py
Traceback (most recent call last):
  File "/home/airflow/.local/lib/python3.6/site-packages/airflow/models/dagbag.py", line 331, in _load_modules_from_file
    loader.exec_module(new_module)
  File "<frozen importlib._bootstrap_external>", line 678, in exec_module
  File "<frozen importlib._bootstrap>", line 219, in _call_with_frames_removed
  File "/opt/airflow/dags/first_dag.py", line 43, in <module>
    provide_context=True
  File "/home/airflow/.local/lib/python3.6/site-packages/airflow/models/baseoperator.py", line 188, in apply_defaults
    result = func(self, *args, **kwargs)
  File "/home/airflow/.local/lib/python3.6/site-packages/airflow/operators/python.py", line 135, in __init__
    super().__init__(**kwargs)
  File "/home/airflow/.local/lib/python3.6/site-packages/airflow/models/baseoperator.py", line 188, in apply_defaults
    result = func(self, *args, **kwargs)
  File "/home/airflow/.local/lib/python3.6/site-packages/airflow/models/baseoperator.py", line 553, in __init__
    task_group.add(self)
  File "/home/airflow/.local/lib/python3.6/site-packages/airflow/utils/task_group.py", line 175, in add
    raise DuplicateTaskIdFound(f"Task id '{key}' has already been added to the DAG")
airflow.exceptions.DuplicateTaskIdFound: Task id 'first_function_execute' has already been added to the DAG
[2021-10-27 07:24:17,436] {processor.py:634} WARNING - No viable dags retrieved from /opt/airflow/dags/first_dag.py
[2021-10-27 07:24:17,445] {processor.py:171} INFO - Processing /opt/airflow/dags/first_dag.py took 0.064 seconds
[2021-10-27 07:24:48,212] {processor.py:163} INFO - Started process (PID=870) to work on /opt/airflow/dags/first_dag.py
[2021-10-27 07:24:48,213] {processor.py:620} INFO - Processing file /opt/airflow/dags/first_dag.py for tasks to queue
[2021-10-27 07:24:48,214] {logging_mixin.py:109} INFO - [2021-10-27 07:24:48,214] {dagbag.py:500} INFO - Filling up the DagBag from /opt/airflow/dags/first_dag.py
[2021-10-27 07:24:48,238] {logging_mixin.py:109} INFO - All Dag modules are ok
[2021-10-27 07:24:48,248] {logging_mixin.py:109} INFO - [2021-10-27 07:24:48,241] {dagbag.py:334} ERROR - Failed to import: /opt/airflow/dags/first_dag.py
Traceback (most recent call last):
  File "/home/airflow/.local/lib/python3.6/site-packages/airflow/models/dagbag.py", line 331, in _load_modules_from_file
    loader.exec_module(new_module)
  File "<frozen importlib._bootstrap_external>", line 678, in exec_module
  File "<frozen importlib._bootstrap>", line 219, in _call_with_frames_removed
  File "/opt/airflow/dags/first_dag.py", line 43, in <module>
    provide_context=True
  File "/home/airflow/.local/lib/python3.6/site-packages/airflow/models/baseoperator.py", line 188, in apply_defaults
    result = func(self, *args, **kwargs)
  File "/home/airflow/.local/lib/python3.6/site-packages/airflow/operators/python.py", line 135, in __init__
    super().__init__(**kwargs)
  File "/home/airflow/.local/lib/python3.6/site-packages/airflow/models/baseoperator.py", line 188, in apply_defaults
    result = func(self, *args, **kwargs)
  File "/home/airflow/.local/lib/python3.6/site-packages/airflow/models/baseoperator.py", line 553, in __init__
    task_group.add(self)
  File "/home/airflow/.local/lib/python3.6/site-packages/airflow/utils/task_group.py", line 175, in add
    raise DuplicateTaskIdFound(f"Task id '{key}' has already been added to the DAG")
airflow.exceptions.DuplicateTaskIdFound: Task id 'first_function_execute' has already been added to the DAG
[2021-10-27 07:24:48,263] {processor.py:634} WARNING - No viable dags retrieved from /opt/airflow/dags/first_dag.py
[2021-10-27 07:24:48,273] {processor.py:171} INFO - Processing /opt/airflow/dags/first_dag.py took 0.065 seconds
[2021-10-27 07:25:18,818] {processor.py:163} INFO - Started process (PID=935) to work on /opt/airflow/dags/first_dag.py
[2021-10-27 07:25:18,820] {processor.py:620} INFO - Processing file /opt/airflow/dags/first_dag.py for tasks to queue
[2021-10-27 07:25:18,821] {logging_mixin.py:109} INFO - [2021-10-27 07:25:18,821] {dagbag.py:500} INFO - Filling up the DagBag from /opt/airflow/dags/first_dag.py
[2021-10-27 07:25:18,847] {logging_mixin.py:109} INFO - All Dag modules are ok
[2021-10-27 07:25:18,855] {logging_mixin.py:109} INFO - [2021-10-27 07:25:18,849] {dagbag.py:334} ERROR - Failed to import: /opt/airflow/dags/first_dag.py
Traceback (most recent call last):
  File "/home/airflow/.local/lib/python3.6/site-packages/airflow/models/dagbag.py", line 331, in _load_modules_from_file
    loader.exec_module(new_module)
  File "<frozen importlib._bootstrap_external>", line 678, in exec_module
  File "<frozen importlib._bootstrap>", line 219, in _call_with_frames_removed
  File "/opt/airflow/dags/first_dag.py", line 43, in <module>
    provide_context=True
  File "/home/airflow/.local/lib/python3.6/site-packages/airflow/models/baseoperator.py", line 188, in apply_defaults
    result = func(self, *args, **kwargs)
  File "/home/airflow/.local/lib/python3.6/site-packages/airflow/operators/python.py", line 135, in __init__
    super().__init__(**kwargs)
  File "/home/airflow/.local/lib/python3.6/site-packages/airflow/models/baseoperator.py", line 188, in apply_defaults
    result = func(self, *args, **kwargs)
  File "/home/airflow/.local/lib/python3.6/site-packages/airflow/models/baseoperator.py", line 553, in __init__
    task_group.add(self)
  File "/home/airflow/.local/lib/python3.6/site-packages/airflow/utils/task_group.py", line 175, in add
    raise DuplicateTaskIdFound(f"Task id '{key}' has already been added to the DAG")
airflow.exceptions.DuplicateTaskIdFound: Task id 'first_function_execute' has already been added to the DAG
[2021-10-27 07:25:18,876] {processor.py:634} WARNING - No viable dags retrieved from /opt/airflow/dags/first_dag.py
[2021-10-27 07:25:18,886] {processor.py:171} INFO - Processing /opt/airflow/dags/first_dag.py took 0.072 seconds
[2021-10-27 07:25:49,024] {processor.py:163} INFO - Started process (PID=991) to work on /opt/airflow/dags/first_dag.py
[2021-10-27 07:25:49,025] {processor.py:620} INFO - Processing file /opt/airflow/dags/first_dag.py for tasks to queue
[2021-10-27 07:25:49,026] {logging_mixin.py:109} INFO - [2021-10-27 07:25:49,026] {dagbag.py:500} INFO - Filling up the DagBag from /opt/airflow/dags/first_dag.py
[2021-10-27 07:25:49,049] {logging_mixin.py:109} INFO - All Dag modules are ok
[2021-10-27 07:25:49,058] {logging_mixin.py:109} INFO - [2021-10-27 07:25:49,051] {dagbag.py:334} ERROR - Failed to import: /opt/airflow/dags/first_dag.py
Traceback (most recent call last):
  File "/home/airflow/.local/lib/python3.6/site-packages/airflow/models/dagbag.py", line 331, in _load_modules_from_file
    loader.exec_module(new_module)
  File "<frozen importlib._bootstrap_external>", line 678, in exec_module
  File "<frozen importlib._bootstrap>", line 219, in _call_with_frames_removed
  File "/opt/airflow/dags/first_dag.py", line 43, in <module>
    provide_context=True
  File "/home/airflow/.local/lib/python3.6/site-packages/airflow/models/baseoperator.py", line 188, in apply_defaults
    result = func(self, *args, **kwargs)
  File "/home/airflow/.local/lib/python3.6/site-packages/airflow/operators/python.py", line 135, in __init__
    super().__init__(**kwargs)
  File "/home/airflow/.local/lib/python3.6/site-packages/airflow/models/baseoperator.py", line 188, in apply_defaults
    result = func(self, *args, **kwargs)
  File "/home/airflow/.local/lib/python3.6/site-packages/airflow/models/baseoperator.py", line 553, in __init__
    task_group.add(self)
  File "/home/airflow/.local/lib/python3.6/site-packages/airflow/utils/task_group.py", line 175, in add
    raise DuplicateTaskIdFound(f"Task id '{key}' has already been added to the DAG")
airflow.exceptions.DuplicateTaskIdFound: Task id 'first_function_execute' has already been added to the DAG
[2021-10-27 07:25:49,075] {processor.py:634} WARNING - No viable dags retrieved from /opt/airflow/dags/first_dag.py
[2021-10-27 07:25:49,085] {processor.py:171} INFO - Processing /opt/airflow/dags/first_dag.py took 0.065 seconds
[2021-10-27 07:26:19,735] {processor.py:163} INFO - Started process (PID=1057) to work on /opt/airflow/dags/first_dag.py
[2021-10-27 07:26:19,736] {processor.py:620} INFO - Processing file /opt/airflow/dags/first_dag.py for tasks to queue
[2021-10-27 07:26:19,737] {logging_mixin.py:109} INFO - [2021-10-27 07:26:19,737] {dagbag.py:500} INFO - Filling up the DagBag from /opt/airflow/dags/first_dag.py
[2021-10-27 07:26:19,758] {logging_mixin.py:109} INFO - All Dag modules are ok
[2021-10-27 07:26:19,767] {logging_mixin.py:109} INFO - [2021-10-27 07:26:19,760] {dagbag.py:334} ERROR - Failed to import: /opt/airflow/dags/first_dag.py
Traceback (most recent call last):
  File "/home/airflow/.local/lib/python3.6/site-packages/airflow/models/dagbag.py", line 331, in _load_modules_from_file
    loader.exec_module(new_module)
  File "<frozen importlib._bootstrap_external>", line 678, in exec_module
  File "<frozen importlib._bootstrap>", line 219, in _call_with_frames_removed
  File "/opt/airflow/dags/first_dag.py", line 43, in <module>
    provide_context=True
  File "/home/airflow/.local/lib/python3.6/site-packages/airflow/models/baseoperator.py", line 188, in apply_defaults
    result = func(self, *args, **kwargs)
  File "/home/airflow/.local/lib/python3.6/site-packages/airflow/operators/python.py", line 135, in __init__
    super().__init__(**kwargs)
  File "/home/airflow/.local/lib/python3.6/site-packages/airflow/models/baseoperator.py", line 188, in apply_defaults
    result = func(self, *args, **kwargs)
  File "/home/airflow/.local/lib/python3.6/site-packages/airflow/models/baseoperator.py", line 553, in __init__
    task_group.add(self)
  File "/home/airflow/.local/lib/python3.6/site-packages/airflow/utils/task_group.py", line 175, in add
    raise DuplicateTaskIdFound(f"Task id '{key}' has already been added to the DAG")
airflow.exceptions.DuplicateTaskIdFound: Task id 'first_function_execute' has already been added to the DAG
[2021-10-27 07:26:19,782] {processor.py:634} WARNING - No viable dags retrieved from /opt/airflow/dags/first_dag.py
[2021-10-27 07:26:19,791] {processor.py:171} INFO - Processing /opt/airflow/dags/first_dag.py took 0.059 seconds
[2021-10-27 07:28:03,028] {processor.py:163} INFO - Started process (PID=43) to work on /opt/airflow/dags/first_dag.py
[2021-10-27 07:28:03,033] {processor.py:620} INFO - Processing file /opt/airflow/dags/first_dag.py for tasks to queue
[2021-10-27 07:28:03,037] {logging_mixin.py:109} INFO - [2021-10-27 07:28:03,037] {dagbag.py:500} INFO - Filling up the DagBag from /opt/airflow/dags/first_dag.py
[2021-10-27 07:28:03,116] {logging_mixin.py:109} INFO - All Dag modules are ok
[2021-10-27 07:28:03,133] {logging_mixin.py:109} INFO - [2021-10-27 07:28:03,124] {dagbag.py:334} ERROR - Failed to import: /opt/airflow/dags/first_dag.py
Traceback (most recent call last):
  File "/home/airflow/.local/lib/python3.6/site-packages/airflow/models/dagbag.py", line 331, in _load_modules_from_file
    loader.exec_module(new_module)
  File "<frozen importlib._bootstrap_external>", line 678, in exec_module
  File "<frozen importlib._bootstrap>", line 219, in _call_with_frames_removed
  File "/opt/airflow/dags/first_dag.py", line 43, in <module>
    provide_context=True
  File "/home/airflow/.local/lib/python3.6/site-packages/airflow/models/baseoperator.py", line 188, in apply_defaults
    result = func(self, *args, **kwargs)
  File "/home/airflow/.local/lib/python3.6/site-packages/airflow/operators/python.py", line 135, in __init__
    super().__init__(**kwargs)
  File "/home/airflow/.local/lib/python3.6/site-packages/airflow/models/baseoperator.py", line 188, in apply_defaults
    result = func(self, *args, **kwargs)
  File "/home/airflow/.local/lib/python3.6/site-packages/airflow/models/baseoperator.py", line 553, in __init__
    task_group.add(self)
  File "/home/airflow/.local/lib/python3.6/site-packages/airflow/utils/task_group.py", line 175, in add
    raise DuplicateTaskIdFound(f"Task id '{key}' has already been added to the DAG")
airflow.exceptions.DuplicateTaskIdFound: Task id 'first_function_execute' has already been added to the DAG
[2021-10-27 07:28:03,165] {processor.py:634} WARNING - No viable dags retrieved from /opt/airflow/dags/first_dag.py
[2021-10-27 07:28:03,182] {processor.py:171} INFO - Processing /opt/airflow/dags/first_dag.py took 0.161 seconds
[2021-10-27 07:28:33,268] {processor.py:163} INFO - Started process (PID=98) to work on /opt/airflow/dags/first_dag.py
[2021-10-27 07:28:33,270] {processor.py:620} INFO - Processing file /opt/airflow/dags/first_dag.py for tasks to queue
[2021-10-27 07:28:33,270] {logging_mixin.py:109} INFO - [2021-10-27 07:28:33,270] {dagbag.py:500} INFO - Filling up the DagBag from /opt/airflow/dags/first_dag.py
[2021-10-27 07:28:33,292] {logging_mixin.py:109} INFO - All Dag modules are ok
[2021-10-27 07:28:33,302] {logging_mixin.py:109} INFO - [2021-10-27 07:28:33,295] {dagbag.py:334} ERROR - Failed to import: /opt/airflow/dags/first_dag.py
Traceback (most recent call last):
  File "/home/airflow/.local/lib/python3.6/site-packages/airflow/models/dagbag.py", line 331, in _load_modules_from_file
    loader.exec_module(new_module)
  File "<frozen importlib._bootstrap_external>", line 678, in exec_module
  File "<frozen importlib._bootstrap>", line 219, in _call_with_frames_removed
  File "/opt/airflow/dags/first_dag.py", line 43, in <module>
    provide_context=True
  File "/home/airflow/.local/lib/python3.6/site-packages/airflow/models/baseoperator.py", line 188, in apply_defaults
    result = func(self, *args, **kwargs)
  File "/home/airflow/.local/lib/python3.6/site-packages/airflow/operators/python.py", line 135, in __init__
    super().__init__(**kwargs)
  File "/home/airflow/.local/lib/python3.6/site-packages/airflow/models/baseoperator.py", line 188, in apply_defaults
    result = func(self, *args, **kwargs)
  File "/home/airflow/.local/lib/python3.6/site-packages/airflow/models/baseoperator.py", line 553, in __init__
    task_group.add(self)
  File "/home/airflow/.local/lib/python3.6/site-packages/airflow/utils/task_group.py", line 175, in add
    raise DuplicateTaskIdFound(f"Task id '{key}' has already been added to the DAG")
airflow.exceptions.DuplicateTaskIdFound: Task id 'first_function_execute' has already been added to the DAG
[2021-10-27 07:28:33,316] {processor.py:634} WARNING - No viable dags retrieved from /opt/airflow/dags/first_dag.py
[2021-10-27 07:28:33,324] {processor.py:171} INFO - Processing /opt/airflow/dags/first_dag.py took 0.058 seconds
[2021-10-27 07:29:03,752] {processor.py:163} INFO - Started process (PID=164) to work on /opt/airflow/dags/first_dag.py
[2021-10-27 07:29:03,754] {processor.py:620} INFO - Processing file /opt/airflow/dags/first_dag.py for tasks to queue
[2021-10-27 07:29:03,755] {logging_mixin.py:109} INFO - [2021-10-27 07:29:03,755] {dagbag.py:500} INFO - Filling up the DagBag from /opt/airflow/dags/first_dag.py
[2021-10-27 07:29:03,784] {logging_mixin.py:109} INFO - All Dag modules are ok
[2021-10-27 07:29:03,794] {logging_mixin.py:109} INFO - [2021-10-27 07:29:03,787] {dagbag.py:334} ERROR - Failed to import: /opt/airflow/dags/first_dag.py
Traceback (most recent call last):
  File "/home/airflow/.local/lib/python3.6/site-packages/airflow/models/dagbag.py", line 331, in _load_modules_from_file
    loader.exec_module(new_module)
  File "<frozen importlib._bootstrap_external>", line 678, in exec_module
  File "<frozen importlib._bootstrap>", line 219, in _call_with_frames_removed
  File "/opt/airflow/dags/first_dag.py", line 43, in <module>
    provide_context=True
  File "/home/airflow/.local/lib/python3.6/site-packages/airflow/models/baseoperator.py", line 188, in apply_defaults
    result = func(self, *args, **kwargs)
  File "/home/airflow/.local/lib/python3.6/site-packages/airflow/operators/python.py", line 135, in __init__
    super().__init__(**kwargs)
  File "/home/airflow/.local/lib/python3.6/site-packages/airflow/models/baseoperator.py", line 188, in apply_defaults
    result = func(self, *args, **kwargs)
  File "/home/airflow/.local/lib/python3.6/site-packages/airflow/models/baseoperator.py", line 553, in __init__
    task_group.add(self)
  File "/home/airflow/.local/lib/python3.6/site-packages/airflow/utils/task_group.py", line 175, in add
    raise DuplicateTaskIdFound(f"Task id '{key}' has already been added to the DAG")
airflow.exceptions.DuplicateTaskIdFound: Task id 'first_function_execute' has already been added to the DAG
[2021-10-27 07:29:03,809] {processor.py:634} WARNING - No viable dags retrieved from /opt/airflow/dags/first_dag.py
[2021-10-27 07:29:03,816] {processor.py:171} INFO - Processing /opt/airflow/dags/first_dag.py took 0.067 seconds
[2021-10-27 07:29:34,167] {processor.py:163} INFO - Started process (PID=220) to work on /opt/airflow/dags/first_dag.py
[2021-10-27 07:29:34,168] {processor.py:620} INFO - Processing file /opt/airflow/dags/first_dag.py for tasks to queue
[2021-10-27 07:29:34,169] {logging_mixin.py:109} INFO - [2021-10-27 07:29:34,169] {dagbag.py:500} INFO - Filling up the DagBag from /opt/airflow/dags/first_dag.py
[2021-10-27 07:29:34,196] {logging_mixin.py:109} INFO - All Dag modules are ok
[2021-10-27 07:29:34,205] {logging_mixin.py:109} INFO - [2021-10-27 07:29:34,199] {dagbag.py:334} ERROR - Failed to import: /opt/airflow/dags/first_dag.py
Traceback (most recent call last):
  File "/home/airflow/.local/lib/python3.6/site-packages/airflow/models/dagbag.py", line 331, in _load_modules_from_file
    loader.exec_module(new_module)
  File "<frozen importlib._bootstrap_external>", line 678, in exec_module
  File "<frozen importlib._bootstrap>", line 219, in _call_with_frames_removed
  File "/opt/airflow/dags/first_dag.py", line 43, in <module>
    provide_context=True
  File "/home/airflow/.local/lib/python3.6/site-packages/airflow/models/baseoperator.py", line 188, in apply_defaults
    result = func(self, *args, **kwargs)
  File "/home/airflow/.local/lib/python3.6/site-packages/airflow/operators/python.py", line 135, in __init__
    super().__init__(**kwargs)
  File "/home/airflow/.local/lib/python3.6/site-packages/airflow/models/baseoperator.py", line 188, in apply_defaults
    result = func(self, *args, **kwargs)
  File "/home/airflow/.local/lib/python3.6/site-packages/airflow/models/baseoperator.py", line 553, in __init__
    task_group.add(self)
  File "/home/airflow/.local/lib/python3.6/site-packages/airflow/utils/task_group.py", line 175, in add
    raise DuplicateTaskIdFound(f"Task id '{key}' has already been added to the DAG")
airflow.exceptions.DuplicateTaskIdFound: Task id 'first_function_execute' has already been added to the DAG
[2021-10-27 07:29:34,221] {processor.py:634} WARNING - No viable dags retrieved from /opt/airflow/dags/first_dag.py
[2021-10-27 07:29:34,232] {processor.py:171} INFO - Processing /opt/airflow/dags/first_dag.py took 0.069 seconds
[2021-10-27 07:30:04,339] {processor.py:163} INFO - Started process (PID=286) to work on /opt/airflow/dags/first_dag.py
[2021-10-27 07:30:04,340] {processor.py:620} INFO - Processing file /opt/airflow/dags/first_dag.py for tasks to queue
[2021-10-27 07:30:04,341] {logging_mixin.py:109} INFO - [2021-10-27 07:30:04,341] {dagbag.py:500} INFO - Filling up the DagBag from /opt/airflow/dags/first_dag.py
[2021-10-27 07:30:04,375] {logging_mixin.py:109} INFO - All Dag modules are ok
[2021-10-27 07:30:04,384] {logging_mixin.py:109} INFO - [2021-10-27 07:30:04,378] {dagbag.py:334} ERROR - Failed to import: /opt/airflow/dags/first_dag.py
Traceback (most recent call last):
  File "/home/airflow/.local/lib/python3.6/site-packages/airflow/models/dagbag.py", line 331, in _load_modules_from_file
    loader.exec_module(new_module)
  File "<frozen importlib._bootstrap_external>", line 678, in exec_module
  File "<frozen importlib._bootstrap>", line 219, in _call_with_frames_removed
  File "/opt/airflow/dags/first_dag.py", line 43, in <module>
    provide_context=True
  File "/home/airflow/.local/lib/python3.6/site-packages/airflow/models/baseoperator.py", line 188, in apply_defaults
    result = func(self, *args, **kwargs)
  File "/home/airflow/.local/lib/python3.6/site-packages/airflow/operators/python.py", line 135, in __init__
    super().__init__(**kwargs)
  File "/home/airflow/.local/lib/python3.6/site-packages/airflow/models/baseoperator.py", line 188, in apply_defaults
    result = func(self, *args, **kwargs)
  File "/home/airflow/.local/lib/python3.6/site-packages/airflow/models/baseoperator.py", line 553, in __init__
    task_group.add(self)
  File "/home/airflow/.local/lib/python3.6/site-packages/airflow/utils/task_group.py", line 175, in add
    raise DuplicateTaskIdFound(f"Task id '{key}' has already been added to the DAG")
airflow.exceptions.DuplicateTaskIdFound: Task id 'first_function_execute' has already been added to the DAG
[2021-10-27 07:30:04,400] {processor.py:634} WARNING - No viable dags retrieved from /opt/airflow/dags/first_dag.py
[2021-10-27 07:30:04,409] {processor.py:171} INFO - Processing /opt/airflow/dags/first_dag.py took 0.073 seconds
[2021-10-27 07:30:30,583] {processor.py:163} INFO - Started process (PID=341) to work on /opt/airflow/dags/first_dag.py
[2021-10-27 07:30:30,584] {processor.py:620} INFO - Processing file /opt/airflow/dags/first_dag.py for tasks to queue
[2021-10-27 07:30:30,586] {logging_mixin.py:109} INFO - [2021-10-27 07:30:30,585] {dagbag.py:500} INFO - Filling up the DagBag from /opt/airflow/dags/first_dag.py
[2021-10-27 07:30:30,607] {logging_mixin.py:109} INFO - All Dag modules are ok
[2021-10-27 07:30:30,611] {logging_mixin.py:109} INFO - [2021-10-27 07:30:30,608] {dagbag.py:334} ERROR - Failed to import: /opt/airflow/dags/first_dag.py
Traceback (most recent call last):
  File "/home/airflow/.local/lib/python3.6/site-packages/airflow/models/dagbag.py", line 331, in _load_modules_from_file
    loader.exec_module(new_module)
  File "<frozen importlib._bootstrap_external>", line 678, in exec_module
  File "<frozen importlib._bootstrap>", line 219, in _call_with_frames_removed
  File "/opt/airflow/dags/first_dag.py", line 20, in <module>
    with DAG(
NameError: name 'DAG' is not defined
[2021-10-27 07:30:30,628] {processor.py:634} WARNING - No viable dags retrieved from /opt/airflow/dags/first_dag.py
[2021-10-27 07:30:30,639] {processor.py:171} INFO - Processing /opt/airflow/dags/first_dag.py took 0.061 seconds
[2021-10-27 07:31:01,044] {processor.py:163} INFO - Started process (PID=395) to work on /opt/airflow/dags/first_dag.py
[2021-10-27 07:31:01,045] {processor.py:620} INFO - Processing file /opt/airflow/dags/first_dag.py for tasks to queue
[2021-10-27 07:31:01,046] {logging_mixin.py:109} INFO - [2021-10-27 07:31:01,046] {dagbag.py:500} INFO - Filling up the DagBag from /opt/airflow/dags/first_dag.py
[2021-10-27 07:31:01,066] {logging_mixin.py:109} INFO - All Dag modules are ok
[2021-10-27 07:31:01,070] {logging_mixin.py:109} INFO - [2021-10-27 07:31:01,067] {dagbag.py:334} ERROR - Failed to import: /opt/airflow/dags/first_dag.py
Traceback (most recent call last):
  File "/home/airflow/.local/lib/python3.6/site-packages/airflow/models/dagbag.py", line 331, in _load_modules_from_file
    loader.exec_module(new_module)
  File "<frozen importlib._bootstrap_external>", line 678, in exec_module
  File "<frozen importlib._bootstrap>", line 219, in _call_with_frames_removed
  File "/opt/airflow/dags/first_dag.py", line 20, in <module>
    with DAG(
NameError: name 'DAG' is not defined
[2021-10-27 07:31:01,086] {processor.py:634} WARNING - No viable dags retrieved from /opt/airflow/dags/first_dag.py
[2021-10-27 07:31:01,095] {processor.py:171} INFO - Processing /opt/airflow/dags/first_dag.py took 0.055 seconds
[2021-10-27 07:31:14,579] {processor.py:163} INFO - Started process (PID=439) to work on /opt/airflow/dags/first_dag.py
[2021-10-27 07:31:14,581] {processor.py:620} INFO - Processing file /opt/airflow/dags/first_dag.py for tasks to queue
[2021-10-27 07:31:14,582] {logging_mixin.py:109} INFO - [2021-10-27 07:31:14,582] {dagbag.py:500} INFO - Filling up the DagBag from /opt/airflow/dags/first_dag.py
[2021-10-27 07:31:14,607] {logging_mixin.py:109} INFO - All Dag modules are ok
[2021-10-27 07:31:14,612] {logging_mixin.py:109} INFO - [2021-10-27 07:31:14,608] {dagbag.py:334} ERROR - Failed to import: /opt/airflow/dags/first_dag.py
Traceback (most recent call last):
  File "/home/airflow/.local/lib/python3.6/site-packages/pep562/__init__.py", line 241, in __getattr__
    return getattr(self._module, name)
AttributeError: module 'airflow' has no attribute 'PythonOperator'

During handling of the above exception, another exception occurred:

Traceback (most recent call last):
  File "/home/airflow/.local/lib/python3.6/site-packages/airflow/models/dagbag.py", line 331, in _load_modules_from_file
    loader.exec_module(new_module)
  File "<frozen importlib._bootstrap_external>", line 678, in exec_module
  File "<frozen importlib._bootstrap>", line 219, in _call_with_frames_removed
  File "/opt/airflow/dags/first_dag.py", line 32, in <module>
    first_function_execute = airflow.PythonOperator(
  File "/home/airflow/.local/lib/python3.6/site-packages/pep562/__init__.py", line 244, in __getattr__
    return self._get_attr(name)
  File "/home/airflow/.local/lib/python3.6/site-packages/airflow/__init__.py", line 66, in __getattr__
    raise AttributeError(f"module {__name__} has no attribute {name}")
AttributeError: module airflow has no attribute PythonOperator
[2021-10-27 07:31:14,628] {processor.py:634} WARNING - No viable dags retrieved from /opt/airflow/dags/first_dag.py
[2021-10-27 07:31:14,640] {processor.py:171} INFO - Processing /opt/airflow/dags/first_dag.py took 0.064 seconds
[2021-10-27 07:31:45,184] {processor.py:163} INFO - Started process (PID=504) to work on /opt/airflow/dags/first_dag.py
[2021-10-27 07:31:45,186] {processor.py:620} INFO - Processing file /opt/airflow/dags/first_dag.py for tasks to queue
[2021-10-27 07:31:45,187] {logging_mixin.py:109} INFO - [2021-10-27 07:31:45,187] {dagbag.py:500} INFO - Filling up the DagBag from /opt/airflow/dags/first_dag.py
[2021-10-27 07:31:45,211] {logging_mixin.py:109} INFO - All Dag modules are ok
[2021-10-27 07:31:45,217] {logging_mixin.py:109} INFO - [2021-10-27 07:31:45,213] {dagbag.py:334} ERROR - Failed to import: /opt/airflow/dags/first_dag.py
Traceback (most recent call last):
  File "/home/airflow/.local/lib/python3.6/site-packages/pep562/__init__.py", line 241, in __getattr__
    return getattr(self._module, name)
AttributeError: module 'airflow' has no attribute 'PythonOperator'

During handling of the above exception, another exception occurred:

Traceback (most recent call last):
  File "/home/airflow/.local/lib/python3.6/site-packages/airflow/models/dagbag.py", line 331, in _load_modules_from_file
    loader.exec_module(new_module)
  File "<frozen importlib._bootstrap_external>", line 678, in exec_module
  File "<frozen importlib._bootstrap>", line 219, in _call_with_frames_removed
  File "/opt/airflow/dags/first_dag.py", line 32, in <module>
    first_function_execute = airflow.PythonOperator(
  File "/home/airflow/.local/lib/python3.6/site-packages/pep562/__init__.py", line 244, in __getattr__
    return self._get_attr(name)
  File "/home/airflow/.local/lib/python3.6/site-packages/airflow/__init__.py", line 66, in __getattr__
    raise AttributeError(f"module {__name__} has no attribute {name}")
AttributeError: module airflow has no attribute PythonOperator
[2021-10-27 07:31:45,235] {processor.py:634} WARNING - No viable dags retrieved from /opt/airflow/dags/first_dag.py
[2021-10-27 07:31:45,245] {processor.py:171} INFO - Processing /opt/airflow/dags/first_dag.py took 0.066 seconds
[2021-10-27 07:32:15,681] {processor.py:163} INFO - Started process (PID=559) to work on /opt/airflow/dags/first_dag.py
[2021-10-27 07:32:15,683] {processor.py:620} INFO - Processing file /opt/airflow/dags/first_dag.py for tasks to queue
[2021-10-27 07:32:15,684] {logging_mixin.py:109} INFO - [2021-10-27 07:32:15,684] {dagbag.py:500} INFO - Filling up the DagBag from /opt/airflow/dags/first_dag.py
[2021-10-27 07:32:15,714] {logging_mixin.py:109} INFO - All Dag modules are ok
[2021-10-27 07:32:15,726] {logging_mixin.py:109} INFO - [2021-10-27 07:32:15,715] {dagbag.py:334} ERROR - Failed to import: /opt/airflow/dags/first_dag.py
Traceback (most recent call last):
  File "/home/airflow/.local/lib/python3.6/site-packages/pep562/__init__.py", line 241, in __getattr__
    return getattr(self._module, name)
AttributeError: module 'airflow' has no attribute 'PythonOperator'

During handling of the above exception, another exception occurred:

Traceback (most recent call last):
  File "/home/airflow/.local/lib/python3.6/site-packages/airflow/models/dagbag.py", line 331, in _load_modules_from_file
    loader.exec_module(new_module)
  File "<frozen importlib._bootstrap_external>", line 678, in exec_module
  File "<frozen importlib._bootstrap>", line 219, in _call_with_frames_removed
  File "/opt/airflow/dags/first_dag.py", line 32, in <module>
    first_function_execute = airflow.PythonOperator(
  File "/home/airflow/.local/lib/python3.6/site-packages/pep562/__init__.py", line 244, in __getattr__
    return self._get_attr(name)
  File "/home/airflow/.local/lib/python3.6/site-packages/airflow/__init__.py", line 66, in __getattr__
    raise AttributeError(f"module {__name__} has no attribute {name}")
AttributeError: module airflow has no attribute PythonOperator
[2021-10-27 07:32:15,745] {processor.py:634} WARNING - No viable dags retrieved from /opt/airflow/dags/first_dag.py
[2021-10-27 07:32:15,752] {processor.py:171} INFO - Processing /opt/airflow/dags/first_dag.py took 0.077 seconds
[2021-10-27 07:32:46,197] {processor.py:163} INFO - Started process (PID=623) to work on /opt/airflow/dags/first_dag.py
[2021-10-27 07:32:46,198] {processor.py:620} INFO - Processing file /opt/airflow/dags/first_dag.py for tasks to queue
[2021-10-27 07:32:46,199] {logging_mixin.py:109} INFO - [2021-10-27 07:32:46,199] {dagbag.py:500} INFO - Filling up the DagBag from /opt/airflow/dags/first_dag.py
[2021-10-27 07:32:46,219] {logging_mixin.py:109} INFO - All Dag modules are ok
[2021-10-27 07:32:46,224] {logging_mixin.py:109} INFO - [2021-10-27 07:32:46,220] {dagbag.py:334} ERROR - Failed to import: /opt/airflow/dags/first_dag.py
Traceback (most recent call last):
  File "/home/airflow/.local/lib/python3.6/site-packages/pep562/__init__.py", line 241, in __getattr__
    return getattr(self._module, name)
AttributeError: module 'airflow' has no attribute 'PythonOperator'

During handling of the above exception, another exception occurred:

Traceback (most recent call last):
  File "/home/airflow/.local/lib/python3.6/site-packages/airflow/models/dagbag.py", line 331, in _load_modules_from_file
    loader.exec_module(new_module)
  File "<frozen importlib._bootstrap_external>", line 678, in exec_module
  File "<frozen importlib._bootstrap>", line 219, in _call_with_frames_removed
  File "/opt/airflow/dags/first_dag.py", line 32, in <module>
    first_function_execute = airflow.PythonOperator(
  File "/home/airflow/.local/lib/python3.6/site-packages/pep562/__init__.py", line 244, in __getattr__
    return self._get_attr(name)
  File "/home/airflow/.local/lib/python3.6/site-packages/airflow/__init__.py", line 66, in __getattr__
    raise AttributeError(f"module {__name__} has no attribute {name}")
AttributeError: module airflow has no attribute PythonOperator
[2021-10-27 07:32:46,243] {processor.py:634} WARNING - No viable dags retrieved from /opt/airflow/dags/first_dag.py
[2021-10-27 07:32:46,255] {processor.py:171} INFO - Processing /opt/airflow/dags/first_dag.py took 0.062 seconds
[2021-10-27 07:33:16,430] {processor.py:163} INFO - Started process (PID=680) to work on /opt/airflow/dags/first_dag.py
[2021-10-27 07:33:16,432] {processor.py:620} INFO - Processing file /opt/airflow/dags/first_dag.py for tasks to queue
[2021-10-27 07:33:16,433] {logging_mixin.py:109} INFO - [2021-10-27 07:33:16,433] {dagbag.py:500} INFO - Filling up the DagBag from /opt/airflow/dags/first_dag.py
[2021-10-27 07:33:16,455] {logging_mixin.py:109} INFO - All Dag modules are ok
[2021-10-27 07:33:16,461] {logging_mixin.py:109} INFO - [2021-10-27 07:33:16,456] {dagbag.py:334} ERROR - Failed to import: /opt/airflow/dags/first_dag.py
Traceback (most recent call last):
  File "/home/airflow/.local/lib/python3.6/site-packages/pep562/__init__.py", line 241, in __getattr__
    return getattr(self._module, name)
AttributeError: module 'airflow' has no attribute 'PythonOperator'

During handling of the above exception, another exception occurred:

Traceback (most recent call last):
  File "/home/airflow/.local/lib/python3.6/site-packages/airflow/models/dagbag.py", line 331, in _load_modules_from_file
    loader.exec_module(new_module)
  File "<frozen importlib._bootstrap_external>", line 678, in exec_module
  File "<frozen importlib._bootstrap>", line 219, in _call_with_frames_removed
  File "/opt/airflow/dags/first_dag.py", line 32, in <module>
    first_function_execute = airflow.PythonOperator(
  File "/home/airflow/.local/lib/python3.6/site-packages/pep562/__init__.py", line 244, in __getattr__
    return self._get_attr(name)
  File "/home/airflow/.local/lib/python3.6/site-packages/airflow/__init__.py", line 66, in __getattr__
    raise AttributeError(f"module {__name__} has no attribute {name}")
AttributeError: module airflow has no attribute PythonOperator
[2021-10-27 07:33:16,475] {processor.py:634} WARNING - No viable dags retrieved from /opt/airflow/dags/first_dag.py
[2021-10-27 07:33:16,484] {processor.py:171} INFO - Processing /opt/airflow/dags/first_dag.py took 0.056 seconds
[2021-10-27 07:33:46,739] {processor.py:163} INFO - Started process (PID=735) to work on /opt/airflow/dags/first_dag.py
[2021-10-27 07:33:46,740] {processor.py:620} INFO - Processing file /opt/airflow/dags/first_dag.py for tasks to queue
[2021-10-27 07:33:46,741] {logging_mixin.py:109} INFO - [2021-10-27 07:33:46,741] {dagbag.py:500} INFO - Filling up the DagBag from /opt/airflow/dags/first_dag.py
[2021-10-27 07:33:46,759] {logging_mixin.py:109} INFO - All Dag modules are ok
[2021-10-27 07:33:46,764] {logging_mixin.py:109} INFO - [2021-10-27 07:33:46,760] {dagbag.py:334} ERROR - Failed to import: /opt/airflow/dags/first_dag.py
Traceback (most recent call last):
  File "/home/airflow/.local/lib/python3.6/site-packages/pep562/__init__.py", line 241, in __getattr__
    return getattr(self._module, name)
AttributeError: module 'airflow' has no attribute 'PythonOperator'

During handling of the above exception, another exception occurred:

Traceback (most recent call last):
  File "/home/airflow/.local/lib/python3.6/site-packages/airflow/models/dagbag.py", line 331, in _load_modules_from_file
    loader.exec_module(new_module)
  File "<frozen importlib._bootstrap_external>", line 678, in exec_module
  File "<frozen importlib._bootstrap>", line 219, in _call_with_frames_removed
  File "/opt/airflow/dags/first_dag.py", line 32, in <module>
    first_function_execute = airflow.PythonOperator(
  File "/home/airflow/.local/lib/python3.6/site-packages/pep562/__init__.py", line 244, in __getattr__
    return self._get_attr(name)
  File "/home/airflow/.local/lib/python3.6/site-packages/airflow/__init__.py", line 66, in __getattr__
    raise AttributeError(f"module {__name__} has no attribute {name}")
AttributeError: module airflow has no attribute PythonOperator
[2021-10-27 07:33:46,779] {processor.py:634} WARNING - No viable dags retrieved from /opt/airflow/dags/first_dag.py
[2021-10-27 07:33:46,788] {processor.py:171} INFO - Processing /opt/airflow/dags/first_dag.py took 0.053 seconds
[2021-10-27 07:34:16,829] {processor.py:163} INFO - Started process (PID=800) to work on /opt/airflow/dags/first_dag.py
[2021-10-27 07:34:16,831] {processor.py:620} INFO - Processing file /opt/airflow/dags/first_dag.py for tasks to queue
[2021-10-27 07:34:16,832] {logging_mixin.py:109} INFO - [2021-10-27 07:34:16,831] {dagbag.py:500} INFO - Filling up the DagBag from /opt/airflow/dags/first_dag.py
[2021-10-27 07:34:16,849] {logging_mixin.py:109} INFO - All Dag modules are ok
[2021-10-27 07:34:16,854] {logging_mixin.py:109} INFO - [2021-10-27 07:34:16,850] {dagbag.py:334} ERROR - Failed to import: /opt/airflow/dags/first_dag.py
Traceback (most recent call last):
  File "/home/airflow/.local/lib/python3.6/site-packages/pep562/__init__.py", line 241, in __getattr__
    return getattr(self._module, name)
AttributeError: module 'airflow' has no attribute 'PythonOperator'

During handling of the above exception, another exception occurred:

Traceback (most recent call last):
  File "/home/airflow/.local/lib/python3.6/site-packages/airflow/models/dagbag.py", line 331, in _load_modules_from_file
    loader.exec_module(new_module)
  File "<frozen importlib._bootstrap_external>", line 678, in exec_module
  File "<frozen importlib._bootstrap>", line 219, in _call_with_frames_removed
  File "/opt/airflow/dags/first_dag.py", line 32, in <module>
    first_function_execute = airflow.PythonOperator(
  File "/home/airflow/.local/lib/python3.6/site-packages/pep562/__init__.py", line 244, in __getattr__
    return self._get_attr(name)
  File "/home/airflow/.local/lib/python3.6/site-packages/airflow/__init__.py", line 66, in __getattr__
    raise AttributeError(f"module {__name__} has no attribute {name}")
AttributeError: module airflow has no attribute PythonOperator
[2021-10-27 07:34:16,869] {processor.py:634} WARNING - No viable dags retrieved from /opt/airflow/dags/first_dag.py
[2021-10-27 07:34:16,879] {processor.py:171} INFO - Processing /opt/airflow/dags/first_dag.py took 0.052 seconds
[2021-10-27 07:34:47,203] {processor.py:163} INFO - Started process (PID=855) to work on /opt/airflow/dags/first_dag.py
[2021-10-27 07:34:47,205] {processor.py:620} INFO - Processing file /opt/airflow/dags/first_dag.py for tasks to queue
[2021-10-27 07:34:47,206] {logging_mixin.py:109} INFO - [2021-10-27 07:34:47,206] {dagbag.py:500} INFO - Filling up the DagBag from /opt/airflow/dags/first_dag.py
[2021-10-27 07:34:47,224] {logging_mixin.py:109} INFO - All Dag modules are ok
[2021-10-27 07:34:47,228] {logging_mixin.py:109} INFO - [2021-10-27 07:34:47,225] {dagbag.py:334} ERROR - Failed to import: /opt/airflow/dags/first_dag.py
Traceback (most recent call last):
  File "/home/airflow/.local/lib/python3.6/site-packages/pep562/__init__.py", line 241, in __getattr__
    return getattr(self._module, name)
AttributeError: module 'airflow' has no attribute 'PythonOperator'

During handling of the above exception, another exception occurred:

Traceback (most recent call last):
  File "/home/airflow/.local/lib/python3.6/site-packages/airflow/models/dagbag.py", line 331, in _load_modules_from_file
    loader.exec_module(new_module)
  File "<frozen importlib._bootstrap_external>", line 678, in exec_module
  File "<frozen importlib._bootstrap>", line 219, in _call_with_frames_removed
  File "/opt/airflow/dags/first_dag.py", line 32, in <module>
    first_function_execute = airflow.PythonOperator(
  File "/home/airflow/.local/lib/python3.6/site-packages/pep562/__init__.py", line 244, in __getattr__
    return self._get_attr(name)
  File "/home/airflow/.local/lib/python3.6/site-packages/airflow/__init__.py", line 66, in __getattr__
    raise AttributeError(f"module {__name__} has no attribute {name}")
AttributeError: module airflow has no attribute PythonOperator
[2021-10-27 07:34:47,244] {processor.py:634} WARNING - No viable dags retrieved from /opt/airflow/dags/first_dag.py
[2021-10-27 07:34:47,254] {processor.py:171} INFO - Processing /opt/airflow/dags/first_dag.py took 0.053 seconds
[2021-10-27 07:35:17,563] {processor.py:163} INFO - Started process (PID=921) to work on /opt/airflow/dags/first_dag.py
[2021-10-27 07:35:17,564] {processor.py:620} INFO - Processing file /opt/airflow/dags/first_dag.py for tasks to queue
[2021-10-27 07:35:17,565] {logging_mixin.py:109} INFO - [2021-10-27 07:35:17,565] {dagbag.py:500} INFO - Filling up the DagBag from /opt/airflow/dags/first_dag.py
[2021-10-27 07:35:17,589] {logging_mixin.py:109} INFO - All Dag modules are ok
[2021-10-27 07:35:17,596] {logging_mixin.py:109} INFO - [2021-10-27 07:35:17,590] {dagbag.py:334} ERROR - Failed to import: /opt/airflow/dags/first_dag.py
Traceback (most recent call last):
  File "/home/airflow/.local/lib/python3.6/site-packages/pep562/__init__.py", line 241, in __getattr__
    return getattr(self._module, name)
AttributeError: module 'airflow' has no attribute 'PythonOperator'

During handling of the above exception, another exception occurred:

Traceback (most recent call last):
  File "/home/airflow/.local/lib/python3.6/site-packages/airflow/models/dagbag.py", line 331, in _load_modules_from_file
    loader.exec_module(new_module)
  File "<frozen importlib._bootstrap_external>", line 678, in exec_module
  File "<frozen importlib._bootstrap>", line 219, in _call_with_frames_removed
  File "/opt/airflow/dags/first_dag.py", line 32, in <module>
    first_function_execute = airflow.PythonOperator(
  File "/home/airflow/.local/lib/python3.6/site-packages/pep562/__init__.py", line 244, in __getattr__
    return self._get_attr(name)
  File "/home/airflow/.local/lib/python3.6/site-packages/airflow/__init__.py", line 66, in __getattr__
    raise AttributeError(f"module {__name__} has no attribute {name}")
AttributeError: module airflow has no attribute PythonOperator
[2021-10-27 07:35:17,610] {processor.py:634} WARNING - No viable dags retrieved from /opt/airflow/dags/first_dag.py
[2021-10-27 07:35:17,618] {processor.py:171} INFO - Processing /opt/airflow/dags/first_dag.py took 0.059 seconds
[2021-10-27 07:35:47,812] {processor.py:163} INFO - Started process (PID=976) to work on /opt/airflow/dags/first_dag.py
[2021-10-27 07:35:47,814] {processor.py:620} INFO - Processing file /opt/airflow/dags/first_dag.py for tasks to queue
[2021-10-27 07:35:47,815] {logging_mixin.py:109} INFO - [2021-10-27 07:35:47,814] {dagbag.py:500} INFO - Filling up the DagBag from /opt/airflow/dags/first_dag.py
[2021-10-27 07:35:47,835] {logging_mixin.py:109} INFO - All Dag modules are ok
[2021-10-27 07:35:47,840] {logging_mixin.py:109} INFO - [2021-10-27 07:35:47,836] {dagbag.py:334} ERROR - Failed to import: /opt/airflow/dags/first_dag.py
Traceback (most recent call last):
  File "/home/airflow/.local/lib/python3.6/site-packages/pep562/__init__.py", line 241, in __getattr__
    return getattr(self._module, name)
AttributeError: module 'airflow' has no attribute 'PythonOperator'

During handling of the above exception, another exception occurred:

Traceback (most recent call last):
  File "/home/airflow/.local/lib/python3.6/site-packages/airflow/models/dagbag.py", line 331, in _load_modules_from_file
    loader.exec_module(new_module)
  File "<frozen importlib._bootstrap_external>", line 678, in exec_module
  File "<frozen importlib._bootstrap>", line 219, in _call_with_frames_removed
  File "/opt/airflow/dags/first_dag.py", line 32, in <module>
    first_function_execute = airflow.PythonOperator(
  File "/home/airflow/.local/lib/python3.6/site-packages/pep562/__init__.py", line 244, in __getattr__
    return self._get_attr(name)
  File "/home/airflow/.local/lib/python3.6/site-packages/airflow/__init__.py", line 66, in __getattr__
    raise AttributeError(f"module {__name__} has no attribute {name}")
AttributeError: module airflow has no attribute PythonOperator
[2021-10-27 07:35:47,855] {processor.py:634} WARNING - No viable dags retrieved from /opt/airflow/dags/first_dag.py
[2021-10-27 07:35:47,864] {processor.py:171} INFO - Processing /opt/airflow/dags/first_dag.py took 0.054 seconds
[2021-10-27 07:36:18,400] {processor.py:163} INFO - Started process (PID=1029) to work on /opt/airflow/dags/first_dag.py
[2021-10-27 07:36:18,410] {processor.py:620} INFO - Processing file /opt/airflow/dags/first_dag.py for tasks to queue
[2021-10-27 07:36:18,414] {logging_mixin.py:109} INFO - [2021-10-27 07:36:18,414] {dagbag.py:500} INFO - Filling up the DagBag from /opt/airflow/dags/first_dag.py
[2021-10-27 07:36:18,461] {logging_mixin.py:109} INFO - All Dag modules are ok
[2021-10-27 07:36:18,476] {logging_mixin.py:109} INFO - [2021-10-27 07:36:18,463] {dagbag.py:334} ERROR - Failed to import: /opt/airflow/dags/first_dag.py
Traceback (most recent call last):
  File "/home/airflow/.local/lib/python3.6/site-packages/pep562/__init__.py", line 241, in __getattr__
    return getattr(self._module, name)
AttributeError: module 'airflow' has no attribute 'PythonOperator'

During handling of the above exception, another exception occurred:

Traceback (most recent call last):
  File "/home/airflow/.local/lib/python3.6/site-packages/airflow/models/dagbag.py", line 331, in _load_modules_from_file
    loader.exec_module(new_module)
  File "<frozen importlib._bootstrap_external>", line 678, in exec_module
  File "<frozen importlib._bootstrap>", line 219, in _call_with_frames_removed
  File "/opt/airflow/dags/first_dag.py", line 32, in <module>
    first_function_execute = airflow.PythonOperator(
  File "/home/airflow/.local/lib/python3.6/site-packages/pep562/__init__.py", line 244, in __getattr__
    return self._get_attr(name)
  File "/home/airflow/.local/lib/python3.6/site-packages/airflow/__init__.py", line 66, in __getattr__
    raise AttributeError(f"module {__name__} has no attribute {name}")
AttributeError: module airflow has no attribute PythonOperator
[2021-10-27 07:36:18,528] {processor.py:634} WARNING - No viable dags retrieved from /opt/airflow/dags/first_dag.py
[2021-10-27 07:36:18,561] {processor.py:171} INFO - Processing /opt/airflow/dags/first_dag.py took 0.166 seconds
[2021-10-27 07:36:48,631] {processor.py:163} INFO - Started process (PID=1082) to work on /opt/airflow/dags/first_dag.py
[2021-10-27 07:36:48,633] {processor.py:620} INFO - Processing file /opt/airflow/dags/first_dag.py for tasks to queue
[2021-10-27 07:36:48,634] {logging_mixin.py:109} INFO - [2021-10-27 07:36:48,634] {dagbag.py:500} INFO - Filling up the DagBag from /opt/airflow/dags/first_dag.py
[2021-10-27 07:36:48,655] {logging_mixin.py:109} INFO - All Dag modules are ok
[2021-10-27 07:36:48,661] {logging_mixin.py:109} INFO - [2021-10-27 07:36:48,656] {dagbag.py:334} ERROR - Failed to import: /opt/airflow/dags/first_dag.py
Traceback (most recent call last):
  File "/home/airflow/.local/lib/python3.6/site-packages/pep562/__init__.py", line 241, in __getattr__
    return getattr(self._module, name)
AttributeError: module 'airflow' has no attribute 'PythonOperator'

During handling of the above exception, another exception occurred:

Traceback (most recent call last):
  File "/home/airflow/.local/lib/python3.6/site-packages/airflow/models/dagbag.py", line 331, in _load_modules_from_file
    loader.exec_module(new_module)
  File "<frozen importlib._bootstrap_external>", line 678, in exec_module
  File "<frozen importlib._bootstrap>", line 219, in _call_with_frames_removed
  File "/opt/airflow/dags/first_dag.py", line 32, in <module>
    first_function_execute = airflow.PythonOperator(
  File "/home/airflow/.local/lib/python3.6/site-packages/pep562/__init__.py", line 244, in __getattr__
    return self._get_attr(name)
  File "/home/airflow/.local/lib/python3.6/site-packages/airflow/__init__.py", line 66, in __getattr__
    raise AttributeError(f"module {__name__} has no attribute {name}")
AttributeError: module airflow has no attribute PythonOperator
[2021-10-27 07:36:48,677] {processor.py:634} WARNING - No viable dags retrieved from /opt/airflow/dags/first_dag.py
[2021-10-27 07:36:48,685] {processor.py:171} INFO - Processing /opt/airflow/dags/first_dag.py took 0.059 seconds
[2021-10-27 07:37:19,124] {processor.py:163} INFO - Started process (PID=1148) to work on /opt/airflow/dags/first_dag.py
[2021-10-27 07:37:19,126] {processor.py:620} INFO - Processing file /opt/airflow/dags/first_dag.py for tasks to queue
[2021-10-27 07:37:19,127] {logging_mixin.py:109} INFO - [2021-10-27 07:37:19,127] {dagbag.py:500} INFO - Filling up the DagBag from /opt/airflow/dags/first_dag.py
[2021-10-27 07:37:19,148] {logging_mixin.py:109} INFO - All Dag modules are ok
[2021-10-27 07:37:19,155] {logging_mixin.py:109} INFO - [2021-10-27 07:37:19,149] {dagbag.py:334} ERROR - Failed to import: /opt/airflow/dags/first_dag.py
Traceback (most recent call last):
  File "/home/airflow/.local/lib/python3.6/site-packages/pep562/__init__.py", line 241, in __getattr__
    return getattr(self._module, name)
AttributeError: module 'airflow' has no attribute 'PythonOperator'

During handling of the above exception, another exception occurred:

Traceback (most recent call last):
  File "/home/airflow/.local/lib/python3.6/site-packages/airflow/models/dagbag.py", line 331, in _load_modules_from_file
    loader.exec_module(new_module)
  File "<frozen importlib._bootstrap_external>", line 678, in exec_module
  File "<frozen importlib._bootstrap>", line 219, in _call_with_frames_removed
  File "/opt/airflow/dags/first_dag.py", line 32, in <module>
    first_function_execute = airflow.PythonOperator(
  File "/home/airflow/.local/lib/python3.6/site-packages/pep562/__init__.py", line 244, in __getattr__
    return self._get_attr(name)
  File "/home/airflow/.local/lib/python3.6/site-packages/airflow/__init__.py", line 66, in __getattr__
    raise AttributeError(f"module {__name__} has no attribute {name}")
AttributeError: module airflow has no attribute PythonOperator
[2021-10-27 07:37:19,178] {processor.py:634} WARNING - No viable dags retrieved from /opt/airflow/dags/first_dag.py
[2021-10-27 07:37:19,187] {processor.py:171} INFO - Processing /opt/airflow/dags/first_dag.py took 0.068 seconds
[2021-10-27 07:37:49,230] {processor.py:163} INFO - Started process (PID=1201) to work on /opt/airflow/dags/first_dag.py
[2021-10-27 07:37:49,231] {processor.py:620} INFO - Processing file /opt/airflow/dags/first_dag.py for tasks to queue
[2021-10-27 07:37:49,232] {logging_mixin.py:109} INFO - [2021-10-27 07:37:49,232] {dagbag.py:500} INFO - Filling up the DagBag from /opt/airflow/dags/first_dag.py
[2021-10-27 07:37:49,251] {logging_mixin.py:109} INFO - All Dag modules are ok
[2021-10-27 07:37:49,256] {logging_mixin.py:109} INFO - [2021-10-27 07:37:49,252] {dagbag.py:334} ERROR - Failed to import: /opt/airflow/dags/first_dag.py
Traceback (most recent call last):
  File "/home/airflow/.local/lib/python3.6/site-packages/pep562/__init__.py", line 241, in __getattr__
    return getattr(self._module, name)
AttributeError: module 'airflow' has no attribute 'PythonOperator'

During handling of the above exception, another exception occurred:

Traceback (most recent call last):
  File "/home/airflow/.local/lib/python3.6/site-packages/airflow/models/dagbag.py", line 331, in _load_modules_from_file
    loader.exec_module(new_module)
  File "<frozen importlib._bootstrap_external>", line 678, in exec_module
  File "<frozen importlib._bootstrap>", line 219, in _call_with_frames_removed
  File "/opt/airflow/dags/first_dag.py", line 32, in <module>
    first_function_execute = airflow.PythonOperator(
  File "/home/airflow/.local/lib/python3.6/site-packages/pep562/__init__.py", line 244, in __getattr__
    return self._get_attr(name)
  File "/home/airflow/.local/lib/python3.6/site-packages/airflow/__init__.py", line 66, in __getattr__
    raise AttributeError(f"module {__name__} has no attribute {name}")
AttributeError: module airflow has no attribute PythonOperator
[2021-10-27 07:37:49,271] {processor.py:634} WARNING - No viable dags retrieved from /opt/airflow/dags/first_dag.py
[2021-10-27 07:37:49,281] {processor.py:171} INFO - Processing /opt/airflow/dags/first_dag.py took 0.054 seconds
[2021-10-27 07:38:19,771] {processor.py:163} INFO - Started process (PID=1253) to work on /opt/airflow/dags/first_dag.py
[2021-10-27 07:38:19,772] {processor.py:620} INFO - Processing file /opt/airflow/dags/first_dag.py for tasks to queue
[2021-10-27 07:38:19,773] {logging_mixin.py:109} INFO - [2021-10-27 07:38:19,773] {dagbag.py:500} INFO - Filling up the DagBag from /opt/airflow/dags/first_dag.py
[2021-10-27 07:38:19,803] {logging_mixin.py:109} INFO - All Dag modules are ok
[2021-10-27 07:38:19,811] {logging_mixin.py:109} INFO - [2021-10-27 07:38:19,805] {dagbag.py:334} ERROR - Failed to import: /opt/airflow/dags/first_dag.py
Traceback (most recent call last):
  File "/home/airflow/.local/lib/python3.6/site-packages/pep562/__init__.py", line 241, in __getattr__
    return getattr(self._module, name)
AttributeError: module 'airflow' has no attribute 'PythonOperator'

During handling of the above exception, another exception occurred:

Traceback (most recent call last):
  File "/home/airflow/.local/lib/python3.6/site-packages/airflow/models/dagbag.py", line 331, in _load_modules_from_file
    loader.exec_module(new_module)
  File "<frozen importlib._bootstrap_external>", line 678, in exec_module
  File "<frozen importlib._bootstrap>", line 219, in _call_with_frames_removed
  File "/opt/airflow/dags/first_dag.py", line 32, in <module>
    first_function_execute = airflow.PythonOperator(
  File "/home/airflow/.local/lib/python3.6/site-packages/pep562/__init__.py", line 244, in __getattr__
    return self._get_attr(name)
  File "/home/airflow/.local/lib/python3.6/site-packages/airflow/__init__.py", line 66, in __getattr__
    raise AttributeError(f"module {__name__} has no attribute {name}")
AttributeError: module airflow has no attribute PythonOperator
[2021-10-27 07:38:19,962] {processor.py:634} WARNING - No viable dags retrieved from /opt/airflow/dags/first_dag.py
[2021-10-27 07:38:19,988] {processor.py:171} INFO - Processing /opt/airflow/dags/first_dag.py took 0.220 seconds
[2021-10-27 07:38:50,179] {processor.py:163} INFO - Started process (PID=1318) to work on /opt/airflow/dags/first_dag.py
[2021-10-27 07:38:50,180] {processor.py:620} INFO - Processing file /opt/airflow/dags/first_dag.py for tasks to queue
[2021-10-27 07:38:50,181] {logging_mixin.py:109} INFO - [2021-10-27 07:38:50,181] {dagbag.py:500} INFO - Filling up the DagBag from /opt/airflow/dags/first_dag.py
[2021-10-27 07:38:50,200] {logging_mixin.py:109} INFO - All Dag modules are ok
[2021-10-27 07:38:50,206] {logging_mixin.py:109} INFO - [2021-10-27 07:38:50,201] {dagbag.py:334} ERROR - Failed to import: /opt/airflow/dags/first_dag.py
Traceback (most recent call last):
  File "/home/airflow/.local/lib/python3.6/site-packages/pep562/__init__.py", line 241, in __getattr__
    return getattr(self._module, name)
AttributeError: module 'airflow' has no attribute 'PythonOperator'

During handling of the above exception, another exception occurred:

Traceback (most recent call last):
  File "/home/airflow/.local/lib/python3.6/site-packages/airflow/models/dagbag.py", line 331, in _load_modules_from_file
    loader.exec_module(new_module)
  File "<frozen importlib._bootstrap_external>", line 678, in exec_module
  File "<frozen importlib._bootstrap>", line 219, in _call_with_frames_removed
  File "/opt/airflow/dags/first_dag.py", line 32, in <module>
    first_function_execute = airflow.PythonOperator(
  File "/home/airflow/.local/lib/python3.6/site-packages/pep562/__init__.py", line 244, in __getattr__
    return self._get_attr(name)
  File "/home/airflow/.local/lib/python3.6/site-packages/airflow/__init__.py", line 66, in __getattr__
    raise AttributeError(f"module {__name__} has no attribute {name}")
AttributeError: module airflow has no attribute PythonOperator
[2021-10-27 07:38:50,221] {processor.py:634} WARNING - No viable dags retrieved from /opt/airflow/dags/first_dag.py
[2021-10-27 07:38:50,227] {processor.py:171} INFO - Processing /opt/airflow/dags/first_dag.py took 0.052 seconds
[2021-10-27 07:39:20,587] {processor.py:163} INFO - Started process (PID=1371) to work on /opt/airflow/dags/first_dag.py
[2021-10-27 07:39:20,589] {processor.py:620} INFO - Processing file /opt/airflow/dags/first_dag.py for tasks to queue
[2021-10-27 07:39:20,590] {logging_mixin.py:109} INFO - [2021-10-27 07:39:20,589] {dagbag.py:500} INFO - Filling up the DagBag from /opt/airflow/dags/first_dag.py
[2021-10-27 07:39:20,611] {logging_mixin.py:109} INFO - All Dag modules are ok
[2021-10-27 07:39:20,616] {logging_mixin.py:109} INFO - [2021-10-27 07:39:20,612] {dagbag.py:334} ERROR - Failed to import: /opt/airflow/dags/first_dag.py
Traceback (most recent call last):
  File "/home/airflow/.local/lib/python3.6/site-packages/pep562/__init__.py", line 241, in __getattr__
    return getattr(self._module, name)
AttributeError: module 'airflow' has no attribute 'PythonOperator'

During handling of the above exception, another exception occurred:

Traceback (most recent call last):
  File "/home/airflow/.local/lib/python3.6/site-packages/airflow/models/dagbag.py", line 331, in _load_modules_from_file
    loader.exec_module(new_module)
  File "<frozen importlib._bootstrap_external>", line 678, in exec_module
  File "<frozen importlib._bootstrap>", line 219, in _call_with_frames_removed
  File "/opt/airflow/dags/first_dag.py", line 32, in <module>
    first_function_execute = airflow.PythonOperator(
  File "/home/airflow/.local/lib/python3.6/site-packages/pep562/__init__.py", line 244, in __getattr__
    return self._get_attr(name)
  File "/home/airflow/.local/lib/python3.6/site-packages/airflow/__init__.py", line 66, in __getattr__
    raise AttributeError(f"module {__name__} has no attribute {name}")
AttributeError: module airflow has no attribute PythonOperator
[2021-10-27 07:39:20,635] {processor.py:634} WARNING - No viable dags retrieved from /opt/airflow/dags/first_dag.py
[2021-10-27 07:39:20,643] {processor.py:171} INFO - Processing /opt/airflow/dags/first_dag.py took 0.060 seconds
[2021-10-27 07:39:50,817] {processor.py:163} INFO - Started process (PID=1434) to work on /opt/airflow/dags/first_dag.py
[2021-10-27 07:39:50,819] {processor.py:620} INFO - Processing file /opt/airflow/dags/first_dag.py for tasks to queue
[2021-10-27 07:39:50,820] {logging_mixin.py:109} INFO - [2021-10-27 07:39:50,820] {dagbag.py:500} INFO - Filling up the DagBag from /opt/airflow/dags/first_dag.py
[2021-10-27 07:39:50,840] {logging_mixin.py:109} INFO - All Dag modules are ok
[2021-10-27 07:39:50,845] {logging_mixin.py:109} INFO - [2021-10-27 07:39:50,841] {dagbag.py:334} ERROR - Failed to import: /opt/airflow/dags/first_dag.py
Traceback (most recent call last):
  File "/home/airflow/.local/lib/python3.6/site-packages/pep562/__init__.py", line 241, in __getattr__
    return getattr(self._module, name)
AttributeError: module 'airflow' has no attribute 'PythonOperator'

During handling of the above exception, another exception occurred:

Traceback (most recent call last):
  File "/home/airflow/.local/lib/python3.6/site-packages/airflow/models/dagbag.py", line 331, in _load_modules_from_file
    loader.exec_module(new_module)
  File "<frozen importlib._bootstrap_external>", line 678, in exec_module
  File "<frozen importlib._bootstrap>", line 219, in _call_with_frames_removed
  File "/opt/airflow/dags/first_dag.py", line 32, in <module>
    first_function_execute = airflow.PythonOperator(
  File "/home/airflow/.local/lib/python3.6/site-packages/pep562/__init__.py", line 244, in __getattr__
    return self._get_attr(name)
  File "/home/airflow/.local/lib/python3.6/site-packages/airflow/__init__.py", line 66, in __getattr__
    raise AttributeError(f"module {__name__} has no attribute {name}")
AttributeError: module airflow has no attribute PythonOperator
[2021-10-27 07:39:50,861] {processor.py:634} WARNING - No viable dags retrieved from /opt/airflow/dags/first_dag.py
[2021-10-27 07:39:50,870] {processor.py:171} INFO - Processing /opt/airflow/dags/first_dag.py took 0.057 seconds
[2021-10-27 07:40:20,911] {processor.py:163} INFO - Started process (PID=1488) to work on /opt/airflow/dags/first_dag.py
[2021-10-27 07:40:20,912] {processor.py:620} INFO - Processing file /opt/airflow/dags/first_dag.py for tasks to queue
[2021-10-27 07:40:20,913] {logging_mixin.py:109} INFO - [2021-10-27 07:40:20,913] {dagbag.py:500} INFO - Filling up the DagBag from /opt/airflow/dags/first_dag.py
[2021-10-27 07:40:20,936] {logging_mixin.py:109} INFO - All Dag modules are ok
[2021-10-27 07:40:20,943] {logging_mixin.py:109} INFO - [2021-10-27 07:40:20,937] {dagbag.py:334} ERROR - Failed to import: /opt/airflow/dags/first_dag.py
Traceback (most recent call last):
  File "/home/airflow/.local/lib/python3.6/site-packages/pep562/__init__.py", line 241, in __getattr__
    return getattr(self._module, name)
AttributeError: module 'airflow' has no attribute 'PythonOperator'

During handling of the above exception, another exception occurred:

Traceback (most recent call last):
  File "/home/airflow/.local/lib/python3.6/site-packages/airflow/models/dagbag.py", line 331, in _load_modules_from_file
    loader.exec_module(new_module)
  File "<frozen importlib._bootstrap_external>", line 678, in exec_module
  File "<frozen importlib._bootstrap>", line 219, in _call_with_frames_removed
  File "/opt/airflow/dags/first_dag.py", line 32, in <module>
    first_function_execute = airflow.PythonOperator(
  File "/home/airflow/.local/lib/python3.6/site-packages/pep562/__init__.py", line 244, in __getattr__
    return self._get_attr(name)
  File "/home/airflow/.local/lib/python3.6/site-packages/airflow/__init__.py", line 66, in __getattr__
    raise AttributeError(f"module {__name__} has no attribute {name}")
AttributeError: module airflow has no attribute PythonOperator
[2021-10-27 07:40:20,988] {processor.py:634} WARNING - No viable dags retrieved from /opt/airflow/dags/first_dag.py
[2021-10-27 07:40:21,000] {processor.py:171} INFO - Processing /opt/airflow/dags/first_dag.py took 0.092 seconds
[2021-10-27 07:40:51,402] {processor.py:163} INFO - Started process (PID=1552) to work on /opt/airflow/dags/first_dag.py
[2021-10-27 07:40:51,404] {processor.py:620} INFO - Processing file /opt/airflow/dags/first_dag.py for tasks to queue
[2021-10-27 07:40:51,404] {logging_mixin.py:109} INFO - [2021-10-27 07:40:51,404] {dagbag.py:500} INFO - Filling up the DagBag from /opt/airflow/dags/first_dag.py
[2021-10-27 07:40:51,422] {logging_mixin.py:109} INFO - All Dag modules are ok
[2021-10-27 07:40:51,426] {logging_mixin.py:109} INFO - [2021-10-27 07:40:51,423] {dagbag.py:334} ERROR - Failed to import: /opt/airflow/dags/first_dag.py
Traceback (most recent call last):
  File "/home/airflow/.local/lib/python3.6/site-packages/pep562/__init__.py", line 241, in __getattr__
    return getattr(self._module, name)
AttributeError: module 'airflow' has no attribute 'PythonOperator'

During handling of the above exception, another exception occurred:

Traceback (most recent call last):
  File "/home/airflow/.local/lib/python3.6/site-packages/airflow/models/dagbag.py", line 331, in _load_modules_from_file
    loader.exec_module(new_module)
  File "<frozen importlib._bootstrap_external>", line 678, in exec_module
  File "<frozen importlib._bootstrap>", line 219, in _call_with_frames_removed
  File "/opt/airflow/dags/first_dag.py", line 32, in <module>
    first_function_execute = airflow.PythonOperator(
  File "/home/airflow/.local/lib/python3.6/site-packages/pep562/__init__.py", line 244, in __getattr__
    return self._get_attr(name)
  File "/home/airflow/.local/lib/python3.6/site-packages/airflow/__init__.py", line 66, in __getattr__
    raise AttributeError(f"module {__name__} has no attribute {name}")
AttributeError: module airflow has no attribute PythonOperator
[2021-10-27 07:40:51,443] {processor.py:634} WARNING - No viable dags retrieved from /opt/airflow/dags/first_dag.py
[2021-10-27 07:40:51,450] {processor.py:171} INFO - Processing /opt/airflow/dags/first_dag.py took 0.051 seconds
[2021-10-27 07:41:21,727] {processor.py:163} INFO - Started process (PID=1606) to work on /opt/airflow/dags/first_dag.py
[2021-10-27 07:41:21,729] {processor.py:620} INFO - Processing file /opt/airflow/dags/first_dag.py for tasks to queue
[2021-10-27 07:41:21,729] {logging_mixin.py:109} INFO - [2021-10-27 07:41:21,729] {dagbag.py:500} INFO - Filling up the DagBag from /opt/airflow/dags/first_dag.py
[2021-10-27 07:41:21,747] {logging_mixin.py:109} INFO - All Dag modules are ok
[2021-10-27 07:41:21,755] {logging_mixin.py:109} INFO - [2021-10-27 07:41:21,748] {dagbag.py:334} ERROR - Failed to import: /opt/airflow/dags/first_dag.py
Traceback (most recent call last):
  File "/home/airflow/.local/lib/python3.6/site-packages/pep562/__init__.py", line 241, in __getattr__
    return getattr(self._module, name)
AttributeError: module 'airflow' has no attribute 'PythonOperator'

During handling of the above exception, another exception occurred:

Traceback (most recent call last):
  File "/home/airflow/.local/lib/python3.6/site-packages/airflow/models/dagbag.py", line 331, in _load_modules_from_file
    loader.exec_module(new_module)
  File "<frozen importlib._bootstrap_external>", line 678, in exec_module
  File "<frozen importlib._bootstrap>", line 219, in _call_with_frames_removed
  File "/opt/airflow/dags/first_dag.py", line 32, in <module>
    first_function_execute = airflow.PythonOperator(
  File "/home/airflow/.local/lib/python3.6/site-packages/pep562/__init__.py", line 244, in __getattr__
    return self._get_attr(name)
  File "/home/airflow/.local/lib/python3.6/site-packages/airflow/__init__.py", line 66, in __getattr__
    raise AttributeError(f"module {__name__} has no attribute {name}")
AttributeError: module airflow has no attribute PythonOperator
[2021-10-27 07:41:21,770] {processor.py:634} WARNING - No viable dags retrieved from /opt/airflow/dags/first_dag.py
[2021-10-27 07:41:21,778] {processor.py:171} INFO - Processing /opt/airflow/dags/first_dag.py took 0.054 seconds
[2021-10-27 07:41:52,347] {processor.py:163} INFO - Started process (PID=1671) to work on /opt/airflow/dags/first_dag.py
[2021-10-27 07:41:52,348] {processor.py:620} INFO - Processing file /opt/airflow/dags/first_dag.py for tasks to queue
[2021-10-27 07:41:52,349] {logging_mixin.py:109} INFO - [2021-10-27 07:41:52,349] {dagbag.py:500} INFO - Filling up the DagBag from /opt/airflow/dags/first_dag.py
[2021-10-27 07:41:52,368] {logging_mixin.py:109} INFO - All Dag modules are ok
[2021-10-27 07:41:52,373] {logging_mixin.py:109} INFO - [2021-10-27 07:41:52,369] {dagbag.py:334} ERROR - Failed to import: /opt/airflow/dags/first_dag.py
Traceback (most recent call last):
  File "/home/airflow/.local/lib/python3.6/site-packages/pep562/__init__.py", line 241, in __getattr__
    return getattr(self._module, name)
AttributeError: module 'airflow' has no attribute 'PythonOperator'

During handling of the above exception, another exception occurred:

Traceback (most recent call last):
  File "/home/airflow/.local/lib/python3.6/site-packages/airflow/models/dagbag.py", line 331, in _load_modules_from_file
    loader.exec_module(new_module)
  File "<frozen importlib._bootstrap_external>", line 678, in exec_module
  File "<frozen importlib._bootstrap>", line 219, in _call_with_frames_removed
  File "/opt/airflow/dags/first_dag.py", line 32, in <module>
    first_function_execute = airflow.PythonOperator(
  File "/home/airflow/.local/lib/python3.6/site-packages/pep562/__init__.py", line 244, in __getattr__
    return self._get_attr(name)
  File "/home/airflow/.local/lib/python3.6/site-packages/airflow/__init__.py", line 66, in __getattr__
    raise AttributeError(f"module {__name__} has no attribute {name}")
AttributeError: module airflow has no attribute PythonOperator
[2021-10-27 07:41:52,388] {processor.py:634} WARNING - No viable dags retrieved from /opt/airflow/dags/first_dag.py
[2021-10-27 07:41:52,396] {processor.py:171} INFO - Processing /opt/airflow/dags/first_dag.py took 0.052 seconds
[2021-10-27 07:42:22,527] {processor.py:163} INFO - Started process (PID=1726) to work on /opt/airflow/dags/first_dag.py
[2021-10-27 07:42:22,528] {processor.py:620} INFO - Processing file /opt/airflow/dags/first_dag.py for tasks to queue
[2021-10-27 07:42:22,529] {logging_mixin.py:109} INFO - [2021-10-27 07:42:22,529] {dagbag.py:500} INFO - Filling up the DagBag from /opt/airflow/dags/first_dag.py
[2021-10-27 07:42:22,550] {logging_mixin.py:109} INFO - All Dag modules are ok
[2021-10-27 07:42:22,556] {logging_mixin.py:109} INFO - [2021-10-27 07:42:22,551] {dagbag.py:334} ERROR - Failed to import: /opt/airflow/dags/first_dag.py
Traceback (most recent call last):
  File "/home/airflow/.local/lib/python3.6/site-packages/pep562/__init__.py", line 241, in __getattr__
    return getattr(self._module, name)
AttributeError: module 'airflow' has no attribute 'PythonOperator'

During handling of the above exception, another exception occurred:

Traceback (most recent call last):
  File "/home/airflow/.local/lib/python3.6/site-packages/airflow/models/dagbag.py", line 331, in _load_modules_from_file
    loader.exec_module(new_module)
  File "<frozen importlib._bootstrap_external>", line 678, in exec_module
  File "<frozen importlib._bootstrap>", line 219, in _call_with_frames_removed
  File "/opt/airflow/dags/first_dag.py", line 32, in <module>
    first_function_execute = airflow.PythonOperator(
  File "/home/airflow/.local/lib/python3.6/site-packages/pep562/__init__.py", line 244, in __getattr__
    return self._get_attr(name)
  File "/home/airflow/.local/lib/python3.6/site-packages/airflow/__init__.py", line 66, in __getattr__
    raise AttributeError(f"module {__name__} has no attribute {name}")
AttributeError: module airflow has no attribute PythonOperator
[2021-10-27 07:42:22,571] {processor.py:634} WARNING - No viable dags retrieved from /opt/airflow/dags/first_dag.py
[2021-10-27 07:42:22,580] {processor.py:171} INFO - Processing /opt/airflow/dags/first_dag.py took 0.055 seconds
[2021-10-27 07:42:52,795] {processor.py:163} INFO - Started process (PID=1792) to work on /opt/airflow/dags/first_dag.py
[2021-10-27 07:42:52,796] {processor.py:620} INFO - Processing file /opt/airflow/dags/first_dag.py for tasks to queue
[2021-10-27 07:42:52,797] {logging_mixin.py:109} INFO - [2021-10-27 07:42:52,797] {dagbag.py:500} INFO - Filling up the DagBag from /opt/airflow/dags/first_dag.py
[2021-10-27 07:42:52,818] {logging_mixin.py:109} INFO - All Dag modules are ok
[2021-10-27 07:42:52,825] {logging_mixin.py:109} INFO - [2021-10-27 07:42:52,819] {dagbag.py:334} ERROR - Failed to import: /opt/airflow/dags/first_dag.py
Traceback (most recent call last):
  File "/home/airflow/.local/lib/python3.6/site-packages/pep562/__init__.py", line 241, in __getattr__
    return getattr(self._module, name)
AttributeError: module 'airflow' has no attribute 'PythonOperator'

During handling of the above exception, another exception occurred:

Traceback (most recent call last):
  File "/home/airflow/.local/lib/python3.6/site-packages/airflow/models/dagbag.py", line 331, in _load_modules_from_file
    loader.exec_module(new_module)
  File "<frozen importlib._bootstrap_external>", line 678, in exec_module
  File "<frozen importlib._bootstrap>", line 219, in _call_with_frames_removed
  File "/opt/airflow/dags/first_dag.py", line 32, in <module>
    first_function_execute = airflow.PythonOperator(
  File "/home/airflow/.local/lib/python3.6/site-packages/pep562/__init__.py", line 244, in __getattr__
    return self._get_attr(name)
  File "/home/airflow/.local/lib/python3.6/site-packages/airflow/__init__.py", line 66, in __getattr__
    raise AttributeError(f"module {__name__} has no attribute {name}")
AttributeError: module airflow has no attribute PythonOperator
[2021-10-27 07:42:52,841] {processor.py:634} WARNING - No viable dags retrieved from /opt/airflow/dags/first_dag.py
[2021-10-27 07:42:52,848] {processor.py:171} INFO - Processing /opt/airflow/dags/first_dag.py took 0.056 seconds
[2021-10-27 07:43:23,626] {processor.py:163} INFO - Started process (PID=1848) to work on /opt/airflow/dags/first_dag.py
[2021-10-27 07:43:23,630] {processor.py:620} INFO - Processing file /opt/airflow/dags/first_dag.py for tasks to queue
[2021-10-27 07:43:23,633] {logging_mixin.py:109} INFO - [2021-10-27 07:43:23,633] {dagbag.py:500} INFO - Filling up the DagBag from /opt/airflow/dags/first_dag.py
[2021-10-27 07:43:23,664] {logging_mixin.py:109} INFO - All Dag modules are ok
[2021-10-27 07:43:23,677] {logging_mixin.py:109} INFO - [2021-10-27 07:43:23,667] {dagbag.py:334} ERROR - Failed to import: /opt/airflow/dags/first_dag.py
Traceback (most recent call last):
  File "/home/airflow/.local/lib/python3.6/site-packages/pep562/__init__.py", line 241, in __getattr__
    return getattr(self._module, name)
AttributeError: module 'airflow' has no attribute 'PythonOperator'

During handling of the above exception, another exception occurred:

Traceback (most recent call last):
  File "/home/airflow/.local/lib/python3.6/site-packages/airflow/models/dagbag.py", line 331, in _load_modules_from_file
    loader.exec_module(new_module)
  File "<frozen importlib._bootstrap_external>", line 678, in exec_module
  File "<frozen importlib._bootstrap>", line 219, in _call_with_frames_removed
  File "/opt/airflow/dags/first_dag.py", line 32, in <module>
    first_function_execute = airflow.PythonOperator(
  File "/home/airflow/.local/lib/python3.6/site-packages/pep562/__init__.py", line 244, in __getattr__
    return self._get_attr(name)
  File "/home/airflow/.local/lib/python3.6/site-packages/airflow/__init__.py", line 66, in __getattr__
    raise AttributeError(f"module {__name__} has no attribute {name}")
AttributeError: module airflow has no attribute PythonOperator
[2021-10-27 07:43:23,736] {processor.py:634} WARNING - No viable dags retrieved from /opt/airflow/dags/first_dag.py
[2021-10-27 07:43:23,752] {processor.py:171} INFO - Processing /opt/airflow/dags/first_dag.py took 0.147 seconds
[2021-10-27 07:43:54,082] {processor.py:163} INFO - Started process (PID=1915) to work on /opt/airflow/dags/first_dag.py
[2021-10-27 07:43:54,087] {processor.py:620} INFO - Processing file /opt/airflow/dags/first_dag.py for tasks to queue
[2021-10-27 07:43:54,089] {logging_mixin.py:109} INFO - [2021-10-27 07:43:54,088] {dagbag.py:500} INFO - Filling up the DagBag from /opt/airflow/dags/first_dag.py
[2021-10-27 07:43:54,110] {logging_mixin.py:109} INFO - All Dag modules are ok
[2021-10-27 07:43:54,116] {logging_mixin.py:109} INFO - [2021-10-27 07:43:54,112] {dagbag.py:334} ERROR - Failed to import: /opt/airflow/dags/first_dag.py
Traceback (most recent call last):
  File "/home/airflow/.local/lib/python3.6/site-packages/pep562/__init__.py", line 241, in __getattr__
    return getattr(self._module, name)
AttributeError: module 'airflow' has no attribute 'PythonOperator'

During handling of the above exception, another exception occurred:

Traceback (most recent call last):
  File "/home/airflow/.local/lib/python3.6/site-packages/airflow/models/dagbag.py", line 331, in _load_modules_from_file
    loader.exec_module(new_module)
  File "<frozen importlib._bootstrap_external>", line 678, in exec_module
  File "<frozen importlib._bootstrap>", line 219, in _call_with_frames_removed
  File "/opt/airflow/dags/first_dag.py", line 32, in <module>
    first_function_execute = airflow.PythonOperator(
  File "/home/airflow/.local/lib/python3.6/site-packages/pep562/__init__.py", line 244, in __getattr__
    return self._get_attr(name)
  File "/home/airflow/.local/lib/python3.6/site-packages/airflow/__init__.py", line 66, in __getattr__
    raise AttributeError(f"module {__name__} has no attribute {name}")
AttributeError: module airflow has no attribute PythonOperator
[2021-10-27 07:43:54,150] {processor.py:634} WARNING - No viable dags retrieved from /opt/airflow/dags/first_dag.py
[2021-10-27 07:43:54,158] {processor.py:171} INFO - Processing /opt/airflow/dags/first_dag.py took 0.082 seconds
[2021-10-27 07:44:24,256] {processor.py:163} INFO - Started process (PID=1971) to work on /opt/airflow/dags/first_dag.py
[2021-10-27 07:44:24,258] {processor.py:620} INFO - Processing file /opt/airflow/dags/first_dag.py for tasks to queue
[2021-10-27 07:44:24,259] {logging_mixin.py:109} INFO - [2021-10-27 07:44:24,259] {dagbag.py:500} INFO - Filling up the DagBag from /opt/airflow/dags/first_dag.py
[2021-10-27 07:44:24,281] {logging_mixin.py:109} INFO - All Dag modules are ok
[2021-10-27 07:44:24,286] {logging_mixin.py:109} INFO - [2021-10-27 07:44:24,282] {dagbag.py:334} ERROR - Failed to import: /opt/airflow/dags/first_dag.py
Traceback (most recent call last):
  File "/home/airflow/.local/lib/python3.6/site-packages/pep562/__init__.py", line 241, in __getattr__
    return getattr(self._module, name)
AttributeError: module 'airflow' has no attribute 'PythonOperator'

During handling of the above exception, another exception occurred:

Traceback (most recent call last):
  File "/home/airflow/.local/lib/python3.6/site-packages/airflow/models/dagbag.py", line 331, in _load_modules_from_file
    loader.exec_module(new_module)
  File "<frozen importlib._bootstrap_external>", line 678, in exec_module
  File "<frozen importlib._bootstrap>", line 219, in _call_with_frames_removed
  File "/opt/airflow/dags/first_dag.py", line 32, in <module>
    first_function_execute = airflow.PythonOperator(
  File "/home/airflow/.local/lib/python3.6/site-packages/pep562/__init__.py", line 244, in __getattr__
    return self._get_attr(name)
  File "/home/airflow/.local/lib/python3.6/site-packages/airflow/__init__.py", line 66, in __getattr__
    raise AttributeError(f"module {__name__} has no attribute {name}")
AttributeError: module airflow has no attribute PythonOperator
[2021-10-27 07:44:24,302] {processor.py:634} WARNING - No viable dags retrieved from /opt/airflow/dags/first_dag.py
[2021-10-27 07:44:24,311] {processor.py:171} INFO - Processing /opt/airflow/dags/first_dag.py took 0.059 seconds
